Workbook

Sheet Data
A1: Fecha | B1: PIBr
A2: 33298 | B2: =+INDEX(Sheet1!$7:$7,MATCH(Data!A2,Sheet1!$4:$4,0)) -> 2730297.5
A3: =+EDATE(A2,3) -> 33390 | B3: =+INDEX(Sheet1!$7:$7,MATCH(Data!A3,Sheet1!$4:$4,0)) -> 2585732.5
A4: =+EDATE(A3,3) -> 33482 | B4: =+INDEX(Sheet1!$7:$7,MATCH(Data!A4,Sheet1!$4:$4,0)) -> 2614916.8
A5: =+EDATE(A4,3) -> 33573 | B5: =+INDEX(Sheet1!$7:$7,MATCH(Data!A5,Sheet1!$4:$4,0)) -> 2873789.5
A6: =+EDATE(A5,3) -> 33664 | B6: =+INDEX(Sheet1!$7:$7,MATCH(Data!A6,Sheet1!$4:$4,0)) -> 2966524.9
A7: =+EDATE(A6,3) -> 33756 | B7: =+INDEX(Sheet1!$7:$7,MATCH(Data!A7,Sheet1!$4:$4,0)) -> 2788824.3
A8: =+EDATE(A7,3) -> 33848 | B8: =+INDEX(Sheet1!$7:$7,MATCH(Data!A8,Sheet1!$4:$4,0)) -> 2963548
A9: =+EDATE(A8,3) -> 33939 | B9: =+INDEX(Sheet1!$7:$7,MATCH(Data!A9,Sheet1!$4:$4,0)) -> 3079994.2
A10: =+EDATE(A9,3) -> 34029 | B10: =+INDEX(Sheet1!$7:$7,MATCH(Data!A10,Sheet1!$4:$4,0)) -> 3217280.3
A11: =+EDATE(A10,3) -> 34121 | B11: =+INDEX(Sheet1!$7:$7,MATCH(Data!A11,Sheet1!$4:$4,0)) -> 2995772.4
A12: =+EDATE(A11,3) -> 34213 | B12: =+INDEX(Sheet1!$7:$7,MATCH(Data!A12,Sheet1!$4:$4,0)) -> 3112130.9
A13: =+EDATE(A12,3) -> 34304 | B13: =+INDEX(Sheet1!$7:$7,MATCH(Data!A13,Sheet1!$4:$4,0)) -> 3311097.7
A14: =+EDATE(A13,3) -> 34394 | B14: =+INDEX(Sheet1!$7:$7,MATCH(Data!A14,Sheet1!$4:$4,0)) -> 3326797.1
... A137: =+EDATE(A136,3) -> 45627 | B137: =+INDEX(Sheet1!$7:$7,MATCH(Data!A137,Sheet1!$4:$4,0)) -> 11289847

Sheet Sheet1
A1: Producto Interno Bruto por Actividad Económica
A2: Volumen a precios del año anterior encadenado, referencia 2017
A3: Millones de colones encadenados y tasas de variación interanual
B4: 33298 | C4: =+EDATE(B4,3) -> 33390 | D4: =+EDATE(C4,3) -> 33482 | E4: =+EDATE(D4,3) -> 33573 | F4: =+EDATE(E4,3) -> 33664 | G4: =+EDATE(F4,3) -> 33756 | H4: =+EDATE(G4,3) -> 33848 | I4: =+EDATE(H4,3) -> 33939 | J4: =+EDATE(I4,3) -> 34029 | ... EG4: =+EDATE(EF4,3) -> 45627
B5: trimestre 1/1991 | C5: trimestre 2/1991 | D5: trimestre 3/1991 | E5: trimestre 4/1991 | F5: trimestre 1/1992 | G5: trimestre 2/1992 | H5: trimestre 3/1992 | I5: trimestre 4/1992 | J5: trimestre 1/1993 | K5: trimestre 2/1993 | L5: trimestre 3/1993 | M5: trimestre 4/1993 | N5: trimestre 1/1994 | O5: trimestre 2/1994 | P5: trimestre 3/1994 | Q5: trimestre 4/1994 | R5: trimestre 1/1995 | S5: trimestre 2/1995 | T5: trimestre 3/1995 | U5: trimestre 4/1995 | V5: trimestre 1/1996 | W5: trimestre 2/1996 | X5: trimestre 3/1996 | Y5: trimestre 4/1996 | Z5: trimestre 1/1997 | AA5: trimestre 2/1997 | AB5: trimestre 3/1997 | AC5: trimestre 4/1997 | AD5: trimestre 1/1998 | AE5: trimestre 2/1998 | AF5: trimestre 3/1998 | AG5: trimestre 4/1998 | AH5: trimestre 1/1999 | AI5: trimestre 2/1999 | AJ5: trimestre 3/1999 | AK5: trimestre 4/1999 | AL5: trimestre 1/2000 | AM5: trimestre 2/2000 | AN5: trimestre 3/2000 | AO5: trimestre 4/2000 | AP5: trimestre 1/2001 | AQ5: trimestre 2/2001 | AR5: trimestre 3/2001 | AS5: trimestre 4/2001 | AT5: trimestre 1/2002 | AU5: trimestre 2/2002 | AV5: trimestre 3/2002 | AW5: trimestre 4/2002 | AX5: trimestre 1/2003 | AY5: trimestre 2/2003 | AZ5: trimestre 3/2003 | BA5: trimestre 4/2003 | BB5: trimestre 1/2004 | BC5: trimestre 2/2004 | BD5: trimestre 3/2004 | BE5: trimestre 4/2004 | BF5: trimestre 1/2005 | BG5: trimestre 2/2005 | BH5: trimestre 3/2005 | BI5: trimestre 4/2005 | BJ5: trimestre 1/2006 | BK5: trimestre 2/2006 | BL5: trimestre 3/2006 | BM5: trimestre 4/2006 | BN5: trimestre 1/2007 | BO5: trimestre 2/2007 | BP5: trimestre 3/2007 | BQ5: trimestre 4/2007 | BR5: trimestre 1/2008 | BS5: trimestre 2/2008 | BT5: trimestre 3/2008 | BU5: trimestre 4/2008 | BV5: trimestre 1/2009 | BW5: trimestre 2/2009 | BX5: trimestre 3/2009 | BY5: trimestre 4/2009 | BZ5: trimestre 1/2010 | CA5: trimestre 2/2010 | CB5: trimestre 3/2010 | CC5: trimestre 4/2010 | CD5: trimestre 1/2011 | CE5: trimestre 2/2011 | CF5: trimestre 3/2011 | CG5: trimestre 4/2011 | CH5: trimestre 1/2012 | CI5: trimestre 2/2012 | CJ5: trimestre 3/2012 | CK5: trimestre 4/2012 | CL5: trimestre 1/2013 | CM5: trimestre 2/2013 | CN5: trimestre 3/2013 | CO5: trimestre 4/2013 | CP5: trimestre 1/2014 | CQ5: trimestre 2/2014 | CR5: trimestre 3/2014 | CS5: trimestre 4/2014 | CT5: trimestre 1/2015 | CU5: trimestre 2/2015 | CV5: trimestre 3/2015 | CW5: trimestre 4/2015 | CX5: trimestre 1/2016 | CY5: trimestre 2/2016 | CZ5: trimestre 3/2016 | DA5: trimestre 4/2016 | DB5: trimestre 1/2017 | DC5: trimestre 2/2017 | DD5: trimestre 3/2017 | DE5: trimestre 4/2017 | DF5: trimestre 1/2018 | DG5: trimestre 2/2018 | DH5: trimestre 3/2018 | DI5: trimestre 4/2018 | DJ5: trimestre 1/2019 | DK5: trimestre 2/2019 | DL5: trimestre 3/2019 | DM5: trimestre 4/2019 | DN5: trimestre 1/2020 | DO5: trimestre 2/2020 | DP5: trimestre 3/2020 | DQ5: trimestre 4/2020 | DR5: trimestre 1/2021 | DS5: trimestre 2/2021 | DT5: trimestre 3/2021 | DU5: trimestre 4/2021 | DV5: trimestre 1/2022 | DW5: trimestre 2/2022 | DX5: trimestre 3/2022 | DY5: trimestre 4/2022 | DZ5: trimestre 1/2023 | EA5: trimestre 2/2023 | EB5: trimestre 3/2023 | EC5: trimestre 4/2023 | ED5: trimestre 1/2024 | EE5: trimestre 2/2024 | EF5: trimestre 3/2024 | EG5: trimestre 4/2024
A6: Millones de colones encadenados
A7: Producto Interno Bruto a precios de mercado | B7: 2730297.5 | C7: 2585732.5 | D7: 2614916.8 | E7: 2873789.5 | F7: 2966524.9 | G7: 2788824.3 | H7: 2963548 | I7: 3079994.2 | J7: 3217280.3 | K7: 2995772.4 | L7: 3112130.9 | M7: 3311097.7 | N7: 3326797.1 | O7: 3204763.9 | P7: 3254567.2 | Q7: 3421190.2 | R7: 3579342.4 | S7: 3296178.6 | T7: 3327731.7 | U7: 3552691.5 | V7: 3565449.9 | W7: 3309375.5 | X7: 3386476 | Y7: 3680411.3 | Z7: 3632809.3 | AA7: 3554621.4 | AB7: 3562232.6 | AC7: 3955520.7 | AD7: 4027204.1 | AE7: 3758269.5 | AF7: 3784925.8 | AG7: 4186985.9 | AH7: 4119646.1 | AI7: 3963344.2 | AJ7: 3982566.7 | AK7: 4355972.2 | AL7: 4355808 | AM7: 4101428.5 | AN7: 4133378.6 | AO7: 4466216.8 | AP7: 4492066.1 | AQ7: 4252053.4 | AR7: 4299652.7 | AS7: 4608542.7 | AT7: 4540875.3 | AU7: 4487161.4 | AV7: 4463358 | AW7: 4764077.9 | AX7: 4777049.7 | AY7: 4616263.4 | AZ7: 4655788.3 | BA7: 4994492.8 | BB7: 4993890.5 | BC7: 4848763.1 | BD7: 4842796.3 | BE7: 5200747.1 | BF7: 5113300.6 | BG7: 5063678.7 | BH7: 5066035.2 | BI7: 5433990.3 | BJ7: 5446096.2 | BK7: 5374475.2 | BL7: 5452618.2 | BM7: 5918756.4 | BN7: 5941002.4 | BO7: 5876424.7 | BP7: 5895618.8 | BQ7: 6301997.6 | BR7: 6353425 | BS7: 6249096.5 | BT7: 6172702 | BU7: 6377694.9 | BV7: 6219210.7 | BW7: 6095089.3 | BX7: 6129267.8 | BY7: 6489650.9 | BZ7: 6543471.4 | CA7: 6444313.8 | CB7: 6485903.7 | CC7: 6796036 | CD7: 6830431.6 | CE7: 6754868.8 | CF7: 6736462.7 | CG7: 7104659.6 | CH7: 7256417.3 | CI7: 7035456.3 | CJ7: 7048732.6 | CK7: 7424937 | CL7: 7367777.3 | CM7: 7232407.2 | CN7: 7278082.1 | CO7: 7604909.6 | CP7: 7695242.7 | CQ7: 7457872 | CR7: 7507164.5 | CS7: 7867223.5 | CT7: 7855849.1 | CU7: 7803052.9 | CV7: 7869383 | CW7: 8114106.9 | CX7: 8211417.5 | CY7: 8104165.1 | CZ7: 8128499.8 | DA7: 8528657.7 | DB7: 8529325.3 | DC7: 8478418.3 | DD7: 8420388.7 | DE7: 8915515.1 | DF7: 8813627.2 | DG7: 8823877.1 | DH7: 8647773.7 | DI7: 8956766.5 | DJ7: 9014522 | DK7: 8889133.6 | DL7: 8867771.9 | DM7: 9322597.5 | DN7: 9162289.1 | DO7: 8176927.2 | DP7: 8269018.7 | DQ7: 8943364.5 | DR7: 9070881.3 | DS7: 9020428.7 | DT7: 9314546.4 | DU7: 9887675.8 | DV7: 9677802.5 | DW7: 9403818.2 | DX7: 9574577.4 | DY7: 10334746 | DZ7: 10108707 | EA7: 9960712.3 | EB7: 10101409 | EC7: 10813302 | ED7: 10469717 | EE7: 10506542 | EF7: 10489041 | EG7: 11289847
A8: Impuestos a los productos y las importaciones | B8: 177591.84 | C8: 174801.66 | D8: 163428.23 | E8: 212085.55 | F8: 205945.14 | G8: 189751.34 | H8: 227222.24 | I8: 233959.14 | J8: 271766.17 | K8: 210058.59 | L8: 237395.08 | M8: 274453.61 | N8: 258206.2 | O8: 241244.07 | P8: 248644.77 | Q8: 301090.31 | R8: 285829.42 | S8: 246231.78 | T8: 261051.36 | U8: 295512.75 | V8: 298235.8 | W8: 267181.97 | X8: 276953.44 | Y8: 366079.82 | Z8: 282226.99 | AA8: 301063.25 | AB8: 284903.01 | AC8: 388426.7 | AD8: 334967.68 | AE8: 319225.22 | AF8: 313876.32 | AG8: 405083.42 | AH8: 344388.25 | AI8: 300053.17 | AJ8: 308296.38 | AK8: 402602.86 | AL8: 347859.73 | AM8: 312431.96 | AN8: 322502.65 | AO8: 436379.23 | AP8: 363946.53 | AQ8: 333501.73 | AR8: 333323.42 | AS8: 436603.18 | AT8: 373282.38 | AU8: 341465.31 | AV8: 336312.57 | AW8: 457823.59 | AX8: 393223.66 | AY8: 355456.73 | AZ8: 354878.22 | BA8: 464987.17 | BB8: 407071.13 | BC8: 360292.06 | BD8: 358749.57 | BE8: 479236.33 | BF8: 411117.77 | BG8: 373763.93 | BH8: 372659.34 | BI8: 480033.12 | BJ8: 429843.89 | BK8: 395107.81 | BL8: 399711.19 | BM8: 524660.2 | BN8: 484057.18 | BO8: 446608.79 | BP8: 459248.55 | BQ8: 573055.24 | BR8: 544573.56 | BS8: 484078.02 | BT8: 473321.24 | BU8: 539406.49 | BV8: 507035.93 | BW8: 434439.62 | BX8: 435883.79 | BY8: 527189.17 | BZ8: 512374.18 | CA8: 456163.23 | CB8: 467166.91 | CC8: 564667.34 | CD8: 548020.45 | CE8: 507312.07 | CF8: 508870.68 | CG8: 576978.8 | CH8: 569100.12 | CI8: 520096.9 | CJ8: 517272.99 | CK8: 583933.08 | CL8: 569680.31 | CM8: 540846.64 | CN8: 541158.16 | CO8: 593868.38 | CP8: 595703.42 | CQ8: 549345.18 | CR8: 550648.85 | CS8: 609526.53 | CT8: 608587.48 | CU8: 577268.68 | CV8: 584711.18 | CW8: 639968.76 | CX8: 654314.69 | CY8: 623060.91 | CZ8: 620299.32 | DA8: 669514.51 | DB8: 678319.69 | DC8: 634783.43 | DD8: 628982.1 | DE8: 682690.68 | DF8: 674577.36 | DG8: 630402.32 | DH8: 626399.55 | DI8: 684658.07 | DJ8: 671028.21 | DK8: 626676.68 | DL8: 631240.95 | DM8: 698672.82 | DN8: 686613.75 | DO8: 541085.89 | DP8: 555576.59 | DQ8: 549065.68 | DR8: 665985.88 | DS8: 618430.37 | DT8: 636249.42 | DU8: 811704.04 | DV8: 714313.74 | DW8: 653921.89 | DX8: 652188.62 | DY8: 881955.87 | DZ8: 736597.08 | EA8: 692799.45 | EB8: 690216.65 | EC8: 931249.05 | ED8: 775646.35 | EE8: 759610.46 | EF8: 710843.87 | EG8: 961403.63
A9: Valor agregado a precios básicos (B1b) | B9: 2558860.7 | C9: 2415486.6 | D9: 2458678.5 | E9: 2663346.3 | F9: 2764796.3 | G9: 2603807.7 | H9: 2736458.2 | I9: 2846650.9 | J9: 2938764.1 | K9: 2790238.3 | L9: 2874669.3 | M9: 3031112.3 | N9: 3066683.2 | O9: 2961931.7 | P9: 3004177 | Q9: 3116897.3 | R9: 3291133.3 | S9: 3048529.3 | T9: 3064695.5 | U9: 3254320.7 | V9: 3263893.5 | W9: 3039815 | X9: 3106835.7 | Y9: 3306751.6 | Z9: 3347800.3 | AA9: 3249731.3 | AB9: 3274239 | AC9: 3560546 | AD9: 3688279.1 | AE9: 3435097 | AF9: 3467401.1 | AG9: 3775343.1 | AH9: 3770056.9 | AI9: 3657435.9 | AJ9: 3668532.8 | AK9: 3948765.9 | AL9: 4003290.8 | AM9: 3785965.8 | AN9: 3807149 | AO9: 4017997.2 | AP9: 4123533.4 | AQ9: 3915927.7 | AR9: 3964283.4 | AS9: 4157322.5 | AT9: 4162249.5 | AU9: 4145726.3 | AV9: 4127720.4 | AW9: 4287799 | AX9: 4378076 | AY9: 4259759.7 | AZ9: 4300509.8 | BA9: 4513544.8 | BB9: 4581291.2 | BC9: 4487910 | BD9: 4483614.3 | BE9: 4708033.3 | BF9: 4697245.1 | BG9: 4690414.6 | BH9: 4694063.2 | BI9: 4941646.9 | BJ9: 5012277.6 | BK9: 4981373 | BL9: 5055196.1 | BM9: 5378131.3 | BN9: 5448774.2 | BO9: 5430146.2 | BP9: 5433825.8 | BQ9: 5704884.1 | BR9: 5792724.6 | BS9: 5763525.5 | BT9: 5699224.5 | BU9: 5824020.2 | BV9: 5703522.3 | BW9: 5668865.3 | BX9: 5701884.8 | BY9: 5953853.3 | BZ9: 6029546 | CA9: 5991955.5 | CB9: 6021696.4 | CC9: 6226234.5 | CD9: 6279660 | CE9: 6248366.1 | CF9: 6228107.9 | CG9: 6524135.3 | CH9: 6685688 | CI9: 6517461.9 | CJ9: 6534003.6 | CK9: 6839129 | CL9: 6797425.1 | CM9: 6692947.2 | CN9: 6738665.9 | CO9: 7009700.2 | CP9: 7098887 | CQ9: 6910640 | CR9: 6958872.3 | CS9: 7256983.9 | CT9: 7246829.5 | CU9: 7227552.3 | CV9: 7286250.9 | CW9: 7472776.4 | CX9: 7556011 | CY9: 7481200 | CZ9: 7508534.6 | DA9: 7858525.3 | DB9: 7850281.8 | DC9: 7843997.7 | DD9: 7791805.6 | DE9: 8232786.4 | DF9: 8139044.2 | DG9: 8193491.1 | DH9: 8021381.3 | DI9: 8272090.6 | DJ9: 8343517.4 | DK9: 8261812 | DL9: 8236007.2 | DM9: 8624051.7 | DN9: 8475204 | DO9: 7636273.2 | DP9: 7713749.7 | DQ9: 8395203.9 | DR9: 8402659.4 | DS9: 8401691 | DT9: 8678049.4 | DU9: 9069565.3 | DV9: 8960597.7 | DW9: 8750687 | DX9: 8924414.6 | DY9: 9439056.2 | DZ9: 9369645.2 | EA9: 9267799.9 | EB9: 9411945.5 | EC9: 9869355.3 | ED9: 9690526.6 | EE9: 9744207.2 | EF9: 9777580 | EG9: 10319093
A10: Agricultura, silvicultura y pesca (A) | B10: 203748.83 | C10: 174110.5 | D10: 170298.31 | E10: 203205.88 | F10: 210508.73 | G10: 192615.59 | H10: 183162.95 | I10: 202831.32 | J10: 217604.97 | K10: 195913.33 | L10: 184753.24 | M10: 223683.1 | N10: 229608.56 | O10: 210014.22 | P10: 203526.89 | Q10: 222931.63 | R10: 260935.1 | S10: 226791.06 | T10: 213203.42 | U10: 247648.42 | V10: 258438.29 | W10: 230771.14 | X10: 227728.46 | Y10: 252476.65 | Z10: 271140.31 | AA10: 253569.08 | AB10: 235823.62 | AC10: 260973.09 | AD10: 304381.56 | AE10: 264472.67 | AF10: 251514.62 | AG10: 283481.98 | AH10: 303356.27 | AI10: 292175.2 | AJ10: 255903.01 | AK10: 293597.99 | AL10: 326580.77 | AM10: 272497.14 | AN10: 250797.08 | AO10: 280049.88 | AP10: 318096.79 | AQ10: 282290.3 | AR10: 260264.49 | AS10: 275917.39 | AT10: 297645.62 | AU10: 286339.32 | AV10: 259939.74 | AW10: 264255.28 | AX10: 312317.25 | AY10: 292272.55 | AZ10: 301979.16 | BA10: 286587.62 | BB10: 321940.91 | BC10: 311949.46 | BD10: 288821.27 | BE10: 297760.07 | BF10: 317461.84 | BG10: 324986.72 | BH10: 301633.62 | BI10: 302257.93 | BJ10: 355269.98 | BK10: 337630.91 | BL10: 328091.24 | BM10: 338994.86 | BN10: 379569.13 | BO10: 368364.71 | BP10: 331300.64 | BQ10: 343378.51 | BR10: 367159.37 | BS10: 358965.17 | BT10: 329655.48 | BU10: 320748.79 | BV10: 336943.78 | BW10: 342720.33 | BX10: 315154.34 | BY10: 335524.48 | BZ10: 369326.58 | CA10: 365190.59 | CB10: 341287.13 | CC10: 338785.24 | CD10: 363153.78 | CE10: 369273.19 | CF10: 338112.56 | CG10: 341779 | CH10: 393529.59 | CI10: 369772.97 | CJ10: 357818.62 | CK10: 360971.37 | CL10: 381240.54 | CM10: 362353.06 | CN10: 359919.28 | CO10: 378743.65 | CP10: 402788.93 | CQ10: 389413.3 | CR10: 359725.4 | CS10: 363442.22 | CT10: 383601.53 | CU10: 381090.15 | CV10: 351726.04 | CW10: 361313.48 | CX10: 405112.31 | CY10: 398834.17 | CZ10: 363526.8 | DA10: 388346.22 | DB10: 411421.78 | DC10: 419302.36 | DD10: 386861.98 | DE10: 396488.5 | DF10: 433223.62 | DG10: 446624.04 | DH10: 396034.57 | DI10: 402887.1 | DJ10: 432893.44 | DK10: 416614.17 | DL10: 402444.2 | DM10: 402219.7 | DN10: 443668.79 | DO10: 403072.44 | DP10: 392284.93 | DQ10: 392463.47 | DR10: 427586.47 | DS10: 436726.01 | DT10: 402774.45 | DU10: 400705.95 | DV10: 422982.67 | DW10: 393886.81 | DX10: 402803.85 | DY10: 409270.06 | DZ10: 429757.31 | EA10: 422461.08 | EB10: 408768.57 | EC10: 424174.74 | ED10: 451460.48 | EE10: 418918.43 | EF10: 422318.65 | EG10: 425851.3
A11: Minas y canteras (B) | B11: 14944.075 | C11: 20454.005 | D11: 17466.851 | E11: 8193.8857 | F11: 18671.33 | G11: 21724.292 | H11: 21193.871 | I11: 11530.104 | J11: 16686.315 | K11: 18736.081 | L11: 17684.473 | M11: 9968.2186 | N11: 18858.639 | O11: 20184.459 | P11: 19145.432 | Q11: 9998.0142 | R11: 19163.94 | S11: 20126.189 | T11: 17771.594 | U11: 8578.2036 | V11: 18496.043 | W11: 19423.196 | X11: 16080.236 | Y11: 8503.7961 | Z11: 17199.325 | AA11: 22140.456 | AB11: 20234.406 | AC11: 11021.531 | AD11: 20372.558 | AE11: 21126.973 | AF11: 20854.443 | AG11: 14773.845 | AH11: 19892.476 | AI11: 19761.75 | AJ11: 19030.278 | AK11: 13754.012 | AL11: 19510.933 | AM11: 19822.874 | AN11: 20609.384 | AO11: 16054.086 | AP11: 20716.018 | AQ11: 21230.088 | AR11: 24143.025 | AS11: 19275.188 | AT11: 22522.067 | AU11: 21235.387 | AV11: 22177.908 | AW11: 17845.237 | AX11: 24358.399 | AY11: 21347.66 | AZ11: 21944.148 | BA11: 18093.51 | BB11: 23269.5 | BC11: 23671.207 | BD11: 23596.682 | BE11: 21525.998 | BF11: 20414.013 | BG11: 21366.331 | BH11: 23614.112 | BI11: 22998.629 | BJ11: 22227.834 | BK11: 25268.982 | BL11: 24690.769 | BM11: 25016.135 | BN11: 23561.329 | BO11: 26881.378 | BP11: 29444.704 | BQ11: 23261.033 | BR11: 25824.762 | BS11: 31362.024 | BT11: 29362.15 | BU11: 24142.865 | BV11: 22231.436 | BW11: 25084.417 | BX11: 23545.284 | BY11: 20870.566 | BZ11: 22274.376 | CA11: 27345.94 | CB11: 26133.143 | CC11: 22176.46 | CD11: 21120.187 | CE11: 24553.591 | CF11: 23240.796 | CG11: 20127.08 | CH11: 20935.289 | CI11: 25423.668 | CJ11: 25060.131 | CK11: 21651.157 | CL11: 22494.329 | CM11: 28091.776 | CN11: 26342.099 | CO11: 21222.152 | CP11: 22803.896 | CQ11: 25217.462 | CR11: 26209.105 | CS11: 25464.345 | CT11: 22724.067 | CU11: 29883.697 | CV11: 30489.083 | CW11: 23972.541 | CX11: 24401.755 | CY11: 29645.485 | CZ11: 29667.673 | DA11: 28384.625 | DB11: 24405.446 | DC11: 24776.266 | DD11: 28515.174 | DE11: 29031.328 | DF11: 27248.338 | DG11: 33585.012 | DH11: 31697.598 | DI11: 28453.723 | DJ11: 25342.354 | DK11: 27266.479 | DL11: 25300.982 | DM11: 27657.129 | DN11: 28019.509 | DO11: 25491.587 | DP11: 25869.975 | DQ11: 28425.483 | DR11: 28780.766 | DS11: 26971.579 | DT11: 25222.595 | DU11: 26038.061 | DV11: 25870.4 | DW11: 25859.311 | DX11: 26331.219 | DY11: 28457.989 | DZ11: 26889.344 | EA11: 26375.738 | EB11: 29282.912 | EC11: 31680.752 | ED11: 30213.546 | EE11: 27072.752 | EF11: 29260.163 | EG11: 30410.844
A12: Manufactura (C) | B12: 533497.58 | C12: 477667.12 | D12: 507013.05 | E12: 615199.31 | F12: 604981.35 | G12: 516823.1 | H12: 596172.42 | I12: 627138.48 | J12: 642459.08 | K12: 553992.96 | L12: 608277.36 | M12: 660364.54 | N12: 643872.14 | O12: 586567.02 | P12: 616762.33 | Q12: 663447.65 | R12: 712893.12 | S12: 576000.47 | T12: 601168.82 | U12: 708436.42 | V12: 699051.51 | W12: 560633.72 | X12: 604836.96 | Y12: 720195.96 | Z12: 711795.21 | AA12: 637955.72 | AB12: 647166.44 | AC12: 782106.06 | AD12: 818246.97 | AE12: 652397.03 | AF12: 651508.36 | AG12: 820933.04 | AH12: 788280.92 | AI12: 680405.28 | AJ12: 697984.59 | AK12: 839509.65 | AL12: 852849.6 | AM12: 724030.7 | AN12: 722179.43 | AO12: 803074.27 | AP12: 844284.39 | AQ12: 715696.82 | AR12: 735540.78 | AS12: 789056.25 | AT12: 799160.57 | AU12: 788527.78 | AV12: 774147.98 | AW12: 829701.46 | AX12: 848419.6 | AY12: 776895.09 | AZ12: 750217.32 | BA12: 859755.21 | BB12: 872086.05 | BC12: 812649.21 | BD12: 786531.08 | BE12: 894099.48 | BF12: 881683.85 | BG12: 846784.33 | BH12: 822785.39 | BI12: 934997.82 | BJ12: 912337.29 | BK12: 857166.56 | BL12: 857773.28 | BM12: 1000174.8 | BN12: 970362.48 | BO12: 895748.69 | BP12: 880398.04 | BQ12: 983722.25 | BR12: 981083.35 | BS12: 901077.84 | BT12: 859789.69 | BU12: 902972.89 | BV12: 866038.35 | BW12: 781226.06 | BX12: 811199.96 | BY12: 895321.71 | BZ12: 939901.39 | CA12: 839793.68 | CB12: 865969.59 | CC12: 937326.78 | CD12: 969695.78 | CE12: 878231.39 | CF12: 878868.5 | CG12: 990909.83 | CH12: 1032212 | CI12: 899851.08 | CJ12: 896413.25 | CK12: 1041676.5 | CL12: 997081.02 | CM12: 919074.04 | CN12: 923261.22 | CO12: 1028223.5 | CP12: 1031034.1 | CQ12: 917356.3 | CR12: 910235.32 | CS12: 1018439.2 | CT12: 970254.31 | CU12: 879473.3 | CV12: 885311.39 | CW12: 983441.59 | CX12: 1002208 | CY12: 930985.2 | CZ12: 923642.17 | DA12: 1019683.8 | DB12: 1038664.3 | DC12: 955525.39 | DD12: 969693.04 | DE12: 1066001.4 | DF12: 1067405.3 | DG12: 1021338.2 | DH12: 1010495.3 | DI12: 1100086 | DJ12: 1096466.8 | DK12: 1040047.9 | DL12: 1040498.8 | DM12: 1148659.8 | DN12: 1172441.5 | DO12: 943568.32 | DP12: 1056559.9 | DQ12: 1245791.5 | DR12: 1266415.4 | DS12: 1253108.1 | DT12: 1290772.6 | DU12: 1405304 | DV12: 1347842.6 | DW12: 1260338.2 | DX12: 1334564.5 | DY12: 1450077.4 | DZ12: 1465800.4 | EA12: 1402613.6 | EB12: 1402438.3 | EC12: 1574953.9 | ED12: 1495934.2 | EE12: 1508663.2 | EF12: 1487550.9 | EG12: 1672624.8
A13: Electricidad, agua y servicios de saneamiento (D, E) | B13: 72108.464 | C13: 74710.645 | D13: 76191.865 | E13: 78406.443 | F13: 78765.692 | G13: 79469.841 | H13: 82419.928 | I13: 82839.299 | J13: 81880.008 | K13: 82475.16 | L13: 83836.22 | M13: 86218.333 | N13: 86660.161 | O13: 89126.997 | P13: 91343.691 | Q13: 92664.627 | R13: 93391.244 | S13: 92546.022 | T13: 92879.814 | U13: 95234.913 | V13: 95087.993 | W13: 96617.636 | X13: 97376.319 | Y13: 99888.924 | Z13: 99518.01 | AA13: 102965.68 | AB13: 105047.81 | AC13: 109646.92 | AD13: 111489.62 | AE13: 113951.9 | AF13: 115834.01 | AG13: 120270.03 | AH13: 121080.38 | AI13: 125215.1 | AJ13: 127627.05 | AK13: 130797.44 | AL13: 130119.65 | AM13: 132990.29 | AN13: 134011.31 | AO13: 138253.83 | AP13: 135934.76 | AQ13: 138635.95 | AR13: 139027.27 | AS13: 140758.83 | AT13: 141112.23 | AU13: 145847.89 | AV13: 145787.24 | AW13: 147572.14 | AX13: 150321.27 | AY13: 152590.55 | AZ13: 151269.34 | BA13: 154805.19 | BB13: 155200.63 | BC13: 157937.31 | BD13: 157847.53 | BE13: 160011.64 | BF13: 162120.32 | BG13: 167150.08 | BH13: 166801.04 | BI13: 168599.69 | BJ13: 172018.51 | BK13: 175206.59 | BL13: 175601.62 | BM13: 177464.91 | BN13: 179950.12 | BO13: 180090.06 | BP13: 180625.95 | BQ13: 180371.83 | BR13: 179496.94 | BS13: 180440.19 | BT13: 178625.39 | BU13: 179542.96 | BV13: 180331.84 | BW13: 184751.46 | BX13: 185879.59 | BY13: 186097.9 | BZ13: 188311.54 | CA13: 191699.39 | CB13: 187489.22 | CC13: 186032.97 | CD13: 187731.41 | CE13: 196431.59 | CF13: 194618.29 | CG13: 200004.38 | CH13: 207504.15 | CI13: 213439.09 | CJ13: 207534.22 | CK13: 195803.79 | CL13: 186875.63 | CM13: 180811.85 | CN13: 170962.25 | CO13: 169900.74 | CP13: 179797.53 | CQ13: 184762.63 | CR13: 183577.07 | CS13: 185678.22 | CT13: 193690.16 | CU13: 204938.84 | CV13: 207167.32 | CW13: 208528.34 | CX13: 212748.19 | CY13: 220178.53 | CZ13: 212445.28 | DA13: 212463.66 | DB13: 218247.54 | DC13: 227572.56 | DD13: 228401.71 | DE13: 225119.96 | DF13: 221278.91 | DG13: 228765.84 | DH13: 222024.67 | DI13: 218810.95 | DJ13: 221478.78 | DK13: 227517.72 | DL13: 225579.82 | DM13: 230107.77 | DN13: 246286.87 | DO13: 236181.54 | DP13: 240729.08 | DQ13: 242233.01 | DR13: 240333.57 | DS13: 246436.61 | DT13: 244510.89 | DU13: 245017.04 | DV13: 248573.01 | DW13: 264693.25 | DX13: 262409.45 | DY13: 259015.09 | DZ13: 257479.34 | EA13: 265780.66 | EB13: 260245.42 | EC13: 256883.51 | ED13: 253178.04 | EE13: 263725.5 | EF13: 251232.1 | EG13: 251639.84
A14: Construcción (F) | B14: 109831.82 | C14: 121894.81 | D14: 120024.77 | E14: 133143.78 | F14: 139532.72 | G14: 135617.79 | H14: 148635.93 | I14: 151272.67 | J14: 162528.95 | K14: 167700.54 | L14: 163132.64 | M14: 164986.22 | N14: 172806.25 | O14: 173495.57 | P14: 177562.21 | Q14: 191160.59 | R14: 203743.19 | S14: 189622.06 | T14: 194302.68 | U14: 189043.03 | V14: 166357.15 | W14: 150989.27 | X14: 154793.8 | Y14: 159661.01 | Z14: 155070.95 | AA14: 155314.29 | AB14: 161463.48 | AC14: 205675.87 | AD14: 211197.28 | AE14: 183279.17 | AF14: 199144.71 | AG14: 210820.19 | AH14: 194590.28 | AI14: 194455.03 | AJ14: 205900.12 | AK14: 208693.07 | AL14: 197050.16 | AM14: 200379.33 | AN14: 217663.59 | AO14: 225599.7 | AP14: 216927.11 | AQ14: 222850.3 | AR14: 267818.29 | AS14: 283922.18 | AT14: 246677.19 | AU14: 229988.59 | AV14: 245389.88 | AW14: 260237.31 | AX14: 276135.69 | AY14: 240197.48 | AZ14: 254110.19 | BA14: 271962.54 | BB14: 270484.67 | BC14: 260384.96 | BD14: 287483.1 | BE14: 293988.78 | BF14: 279346.44 | BG14: 254755.5 | BH14: 291929.38 | BI14: 299251.46 | BJ14: 305134.5 | BK14: 294413.97 | BL14: 334542.97 | BM14: 342270.25 | BN14: 366168.06 | BO14: 385094.7 | BP14: 406015.11 | BQ14: 398390.45 | BR14: 422186.97 | BS14: 423922.37 | BT14: 434397.61 | BU14: 437030.06 | BV14: 418255.85 | BW14: 419589.89 | BX14: 425910.34 | BY14: 420514.21 | BZ14: 399942.57 | CA14: 396063.56 | CB14: 400407.09 | CC14: 401165.71 | CD14: 392151.59 | CE14: 398341.88 | CF14: 413170.45 | CG14: 418432.55 | CH14: 433024.32 | CI14: 404414.77 | CJ14: 421764.86 | CK14: 397835.88 | CL14: 377685.93 | CM14: 380347.25 | CN14: 415057.48 | CO14: 362889.85 | CP14: 382812.79 | CQ14: 332876.96 | CR14: 417151.19 | CS14: 426138.64 | CT14: 395587.72 | CU14: 431675.47 | CV14: 479277.58 | CW14: 386777.68 | CX14: 384370.16 | CY14: 368261.02 | CZ14: 439907.25 | DA14: 474566.79 | DB14: 419476.99 | DC14: 410708.27 | DD14: 329439.16 | DE14: 437738.88 | DF14: 358840.59 | DG14: 426061.84 | DH14: 402412.77 | DI14: 410241.38 | DJ14: 357461.71 | DK14: 351834.51 | DL14: 335453.7 | DM14: 410186.32 | DN14: 333715.73 | DO14: 401775.1 | DP14: 335621.96 | DQ14: 370418.81 | DR14: 325308.46 | DS14: 384537.08 | DT14: 395206.6 | DU14: 381629.85 | DV14: 385539 | DW14: 325756.75 | DX14: 312839.52 | DY14: 389455.45 | DZ14: 376059.84 | EA14: 388027.51 | EB14: 442216.37 | EC14: 398102.13 | ED14: 366419.45 | EE14: 428519.57 | EF14: 402485.87 | EG14: 462476.52
A15: Comercio al por mayor y al por menor, reparación de vehículos (G) | B15: 349668.51 | C15: 331454.27 | D15: 326486 | E15: 327548.42 | F15: 385577.84 | G15: 356481.54 | H15: 363064.07 | I15: 368352.39 | J15: 409546.13 | K15: 382671.61 | L15: 387756.62 | M15: 385342.39 | N15: 414098.39 | O15: 400046.37 | P15: 389981.15 | Q15: 391123.43 | R15: 424986.52 | S15: 397648.03 | T15: 388898.62 | U15: 390043.14 | V15: 392271.03 | W15: 369838.95 | X15: 378443.26 | Y15: 396701.5 | Z15: 383838.39 | AA15: 384660.06 | AB15: 400682.86 | AC15: 427065.39 | AD15: 418528.28 | AE15: 408260.88 | AF15: 411750.07 | AG15: 423543.44 | AH15: 406731.13 | AI15: 394920.94 | AJ15: 400393.31 | AK15: 419565.66 | AL15: 401421.19 | AM15: 387983.43 | AN15: 399583.8 | AO15: 429935.27 | AP15: 419850.63 | AQ15: 399225.25 | AR15: 399224.1 | AS15: 449776.34 | AT15: 415471 | AU15: 417359.33 | AV15: 418034.53 | AW15: 465606.63 | AX15: 430321.9 | AY15: 417132.95 | AZ15: 431708.69 | BA15: 482038.98 | BB15: 457146.58 | BC15: 431090.15 | BD15: 434598.26 | BE15: 476414.34 | BF15: 441200.92 | BG15: 438509.02 | BH15: 448744.15 | BI15: 504342.02 | BJ15: 475667.96 | BK15: 474104.37 | BL15: 486226.84 | BM15: 544692.06 | BN15: 517824.39 | BO15: 513985.6 | BP15: 522356.36 | BQ15: 597658.1 | BR15: 554866.42 | BS15: 561989.96 | BT15: 557327.1 | BU15: 595962.21 | BV15: 524043 | BW15: 516380.7 | BX15: 520155.3 | BY15: 583555.66 | BZ15: 543845.26 | CA15: 554579.93 | CB15: 549701.05 | CC15: 632864.39 | CD15: 585049.58 | CE15: 588278.99 | CF15: 570897.47 | CG15: 663353.16 | CH15: 617771.59 | CI15: 608927.48 | CJ15: 594082.46 | CK15: 685646.33 | CL15: 644678.43 | CM15: 641564.32 | CN15: 634111.55 | CO15: 720226.72 | CP15: 677905.13 | CQ15: 666062.26 | CR15: 648209.64 | CS15: 742483.7 | CT15: 704941.36 | CU15: 690398.75 | CV15: 683975.57 | CW15: 771047.4 | CX15: 720355.5 | CY15: 723421.2 | CZ15: 712637.49 | DA15: 811072.31 | DB15: 771618.3 | DC15: 776838.63 | DD15: 770999.41 | DE15: 854067.79 | DF15: 803777.31 | DG15: 808023.58 | DH15: 777845.18 | DI15: 854645.57 | DJ15: 802617.07 | DK15: 797844.51 | DL15: 777418.15 | DM15: 879316.05 | DN15: 809114.25 | DO15: 692636.41 | DP15: 685763.41 | DQ15: 814693.17 | DR15: 827423.31 | DS15: 780229.23 | DT15: 765215.78 | DU15: 873305.95 | DV15: 865729.33 | DW15: 813341.02 | DX15: 780308.49 | DY15: 892768.84 | DZ15: 877537.23 | EA15: 832540.75 | EB15: 815245.46 | EC15: 945485.97 | ED15: 916278.3 | EE15: 876860.25 | EF15: 844137.67 | EG15: 970224.89
A16: Transporte y almacenamiento (H) | B16: 170520.29 | C16: 172024.46 | D16: 170320.5 | E16: 174849.27 | F16: 176565.95 | G16: 181309.38 | H16: 180749.66 | I16: 182053.7 | J16: 188810.91 | K16: 189711.18 | L16: 188453.12 | M16: 188611.48 | N16: 191242.12 | O16: 188102.01 | P16: 185674.2 | Q16: 180403.36 | R16: 182009.41 | S16: 180174.65 | T16: 175446.54 | U16: 173552.96 | V16: 172287.41 | W16: 168750.73 | X16: 165198.15 | Y16: 165667.91 | Z16: 168231.94 | AA16: 169656.65 | AB16: 165321.91 | AC16: 168760.59 | AD16: 171876.09 | AE16: 172898.88 | AF16: 167216.29 | AG16: 168104.3 | AH16: 166350.72 | AI16: 166742.9 | AJ16: 164172.16 | AK16: 168011.29 | AL16: 174225.01 | AM16: 176593.4 | AN16: 176869.47 | AO16: 179636.89 | AP16: 179201.57 | AQ16: 179062.75 | AR16: 175135.74 | AS16: 176011.81 | AT16: 176632.1 | AU16: 177912.21 | AV16: 177025.38 | AW16: 179823.33 | AX16: 186586.65 | AY16: 189857.08 | AZ16: 191324.53 | BA16: 195098.78 | BB16: 202205.25 | BC16: 204090.36 | BD16: 205852.69 | BE16: 210102.99 | BF16: 214103.72 | BG16: 219044.24 | BH16: 220149.61 | BI16: 221173.65 | BJ16: 228034.94 | BK16: 233518.41 | BL16: 238263.56 | BM16: 243079.8 | BN16: 248981.11 | BO16: 255352.47 | BP16: 259526.86 | BQ16: 258098.98 | BR16: 264643.2 | BS16: 271724.68 | BT16: 267870.03 | BU16: 264305.17 | BV16: 258166.54 | BW16: 258080.58 | BX16: 255290.4 | BY16: 258654.74 | BZ16: 267538.49 | CA16: 275338.85 | CB16: 274690.13 | CC16: 278747.28 | CD16: 290439.55 | CE16: 295720.62 | CF16: 298437.39 | CG16: 302558.21 | CH16: 311903.52 | CI16: 313975.07 | CJ16: 316046.82 | CK16: 317504.87 | CL16: 319776.35 | CM16: 322681.19 | CN16: 318231.44 | CO16: 320822.42 | CP16: 325437.43 | CQ16: 329460.8 | CR16: 335740.92 | CS16: 339714.86 | CT16: 347152.08 | CU16: 349307.73 | CV16: 349616.75 | CW16: 349882.45 | CX16: 354184.11 | CY16: 358549.61 | CZ16: 355471.59 | DA16: 359931.59 | DB16: 372592.83 | DC16: 383965.59 | DD16: 386081.79 | DE16: 397350.93 | DF16: 404598.29 | DG16: 413271.57 | DH16: 407452.39 | DI16: 405130.85 | DJ16: 398711.69 | DK16: 401249.9 | DL16: 399856.32 | DM16: 412567.06 | DN16: 415639.1 | DO16: 297356.72 | DP16: 302547.57 | DQ16: 326350.31 | DR16: 359083.05 | DS16: 377999.21 | DT16: 370821.33 | DU16: 383149.15 | DV16: 388713 | DW16: 414468.18 | DX16: 399194.14 | DY16: 411822.32 | DZ16: 401161.01 | EA16: 431414.01 | EB16: 422058.64 | EC16: 441657.58 | ED16: 431391.41 | EE16: 467777 | EF16: 455182.18 | EG16: 473501.7
A17: Actividades de alojamiento y servicios de comida (I) | B17: 84761.656 | C17: 76601.44 | D17: 79965.977 | E17: 85190.418 | F17: 94429.624 | G17: 87060.187 | H17: 91297.666 | I17: 95734.459 | J17: 103253.08 | K17: 93128.747 | L17: 95895.66 | M17: 99541.903 | N17: 106269.73 | O17: 95255.076 | P17: 97614.534 | Q17: 100934.08 | R17: 107365.02 | S17: 96178.752 | T17: 98689.442 | U17: 102452.48 | V17: 109568.09 | W17: 98459.778 | X17: 100678.18 | Y17: 103797.73 | Z17: 109501.06 | AA17: 98692.178 | AB17: 102503.06 | AC17: 109029.75 | AD17: 119604.54 | AE17: 110212.5 | AF17: 114781.84 | AG17: 119981.83 | AH17: 127271.4 | AI17: 114789.16 | AJ17: 118779.76 | AK17: 125133.61 | AL17: 136126.06 | AM17: 124444.12 | AN17: 129583.97 | AO17: 135981.98 | AP17: 151854.89 | AQ17: 130587.33 | AR17: 133443.87 | AS17: 137902.73 | AT17: 153027.09 | AU17: 133325.2 | AV17: 136130.24 | AW17: 142559.69 | AX17: 157400.01 | AY17: 139634.88 | AZ17: 147010.73 | BA17: 150874.45 | BB17: 175418.83 | BC17: 148992.22 | BD17: 153767.86 | BE17: 162894.38 | BF17: 185681.22 | BG17: 160901.76 | BH17: 163094.99 | BI17: 168755.02 | BJ17: 191850.29 | BK17: 166324.88 | BL17: 166355.89 | BM17: 174162.51 | BN17: 197644.72 | BO17: 176088.52 | BP17: 180495.68 | BQ17: 188670.16 | BR17: 216963.56 | BS17: 187705.85 | BT17: 186879.57 | BU17: 183013.72 | BV17: 187370.08 | BW17: 169662.24 | BX17: 180659.12 | BY17: 180020.71 | BZ17: 215338.59 | CA17: 188031.74 | CB17: 203973 | CC17: 196296.95 | CD17: 226520.78 | CE17: 197473.36 | CF17: 200883.44 | CG17: 199028.81 | CH17: 232129.89 | CI17: 198709.03 | CJ17: 205863.5 | CK17: 211950.1 | CL17: 251478.61 | CM17: 223169.29 | CN17: 230569.76 | CO17: 240229.41 | CP17: 281159.66 | CQ17: 242057.26 | CR17: 247221.8 | CS17: 255503.36 | CT17: 294461.52 | CU17: 254924.05 | CV17: 261695.75 | CW17: 268740.09 | CX17: 310308.87 | CY17: 269212.67 | CZ17: 273036.41 | DA17: 271295.14 | DB17: 315121.45 | DC17: 277802.31 | DD17: 276142.84 | DE17: 280832.61 | DF17: 327971.74 | DG17: 280238.07 | DH17: 276164.72 | DI17: 280059.71 | DJ17: 327818.76 | DK17: 284428.36 | DL17: 289994.71 | DM17: 305995.82 | DN17: 337108.93 | DO17: 132676.93 | DP17: 133945.6 | DQ17: 166481.39 | DR17: 206829.84 | DS17: 202705.2 | DT17: 241230.37 | DU17: 259754.21 | DV17: 268717.23 | DW17: 230495.03 | DX17: 258305.41 | DY17: 277571.47 | DZ17: 298123.28 | EA17: 244920.28 | EB17: 282060.89 | EC17: 295393.41 | ED17: 321148.86 | EE17: 263437.28 | EF17: 294191.13 | EG17: 297233.95
A18: Información y comunicaciones (J) | B18: 14493.119 | C18: 15190.503 | D18: 15273.488 | E18: 15523.305 | F18: 15791.568 | G18: 15553.091 | H18: 16605 | I18: 17599.905 | J18: 17380.061 | K18: 17610.294 | L18: 18853.474 | M18: 19036.803 | N18: 19262.085 | O18: 19722.789 | P18: 20104.054 | Q18: 21378.535 | R18: 22827.007 | S18: 22694.173 | T18: 22743.036 | U18: 22496.659 | V18: 23367.45 | W18: 22910.56 | X18: 22822.021 | Y18: 24598.3 | Z18: 25140.493 | AA18: 26347.525 | AB18: 26841.434 | AC18: 28985.098 | AD18: 27951.636 | AE18: 28047.875 | AF18: 28820.37 | AG18: 31896.824 | AH18: 32231.813 | AI18: 33852.561 | AJ18: 35056.243 | AK18: 36139.942 | AL18: 39430.619 | AM18: 40932.779 | AN18: 42482.846 | AO18: 45009.104 | AP18: 47640.588 | AQ18: 50110.822 | AR18: 53371.793 | AS18: 56796.621 | AT18: 59645.101 | AU18: 60414.941 | AV18: 62465.065 | AW18: 65468.092 | AX18: 71239.541 | AY18: 73247.871 | AZ18: 76255.699 | BA18: 82366.734 | BB18: 88641.303 | BC18: 88331.596 | BD18: 91947.942 | BE18: 93654.602 | BF18: 98887.656 | BG18: 100924.75 | BH18: 104786.78 | BI18: 108614.48 | BJ18: 117179.28 | BK18: 119478.16 | BL18: 124371.73 | BM18: 127326.2 | BN18: 129077.6 | BO18: 131825.27 | BP18: 135547.02 | BQ18: 139320.06 | BR18: 144944.06 | BS18: 148494.69 | BT18: 151103.86 | BU18: 155925.81 | BV18: 161665.41 | BW18: 164472.46 | BX18: 170719.26 | BY18: 178050.44 | BZ18: 189710.09 | CA18: 197055.36 | CB18: 204976.34 | CC18: 210795.82 | CD18: 220949.71 | CE18: 224170.62 | CF18: 229713.6 | CG18: 234661.08 | CH18: 243828.54 | CI18: 247375.27 | CJ18: 248989.82 | CK18: 254091.51 | CL18: 259000.79 | CM18: 260417.22 | CN18: 266872.29 | CO18: 274340.45 | CP18: 282318.86 | CQ18: 280581.31 | CR18: 291607.63 | CS18: 296724.9 | CT18: 311579.93 | CU18: 317290.43 | CV18: 322557.83 | CW18: 327540.19 | CX18: 335963.28 | CY18: 332021.58 | CZ18: 333294.14 | DA18: 341642.4 | DB18: 358934.81 | DC18: 377900.69 | DD18: 397974.07 | DE18: 415684.22 | DF18: 392738.3 | DG18: 385715.56 | DH18: 379276.72 | DI18: 388815.52 | DJ18: 395532.52 | DK18: 390788.22 | DL18: 401304.75 | DM18: 413812.61 | DN18: 411745.43 | DO18: 401049.92 | DP18: 408796.12 | DQ18: 408878.47 | DR18: 426047.58 | DS18: 428847.22 | DT18: 442493.01 | DU18: 459074.41 | DV18: 461223.21 | DW18: 508227.83 | DX18: 519394.98 | DY18: 513088.78 | DZ18: 502272.13 | EA18: 528787.9 | EB18: 529699.92 | EC18: 531941.37 | ED18: 529658.67 | EE18: 569833.93 | EF18: 559039.03 | EG18: 567918.12
... A24: Otras actividades (R, S, T, U) | B24: 120154.44 | C24: 120237.69 | D24: 120438.38 | E24: 120824.32 | F24: 121099.66 | G24: 122084.26 | H24: 123747.51 | I24: 126139.12 | J24: 128318.05 | K24: 130411.56 | L24: 131944.69 | M24: 132921.96 | N24: 132117.87 | O24: 131935.16 | P24: 131799.11 | Q24: 131749.21 | R24: 129363.77 | S24: 128875.65 | T24: 128944.38 | U24: 129581.48 | V24: 128514.86 | W24: 128736.32 | X24: 129074.32 | Y24: 129645.11 | Z24: 126324.9 | AA24: 126427.46 | AB24: 127566.66 | AC24: 129676.24 | AD24: 128329.38 | AE24: 129867.82 | AF24: 131705.38 | AG24: 133861.29 | AH24: 132398.36 | AI24: 133677.73 | AJ24: 135255.78 | AK24: 136936.22 | AL24: 136295.57 | AM24: 137222.37 | AN24: 138228.82 | AO24: 139356.85 | AP24: 140577.17 | AQ24: 142046.6 | AR24: 143730.39 | AS24: 145621.05 | AT24: 147695.83 | AU24: 149048.96 | AV24: 149693.08 | AW24: 149631.74 | AX24: 148835.42 | AY24: 148291.59 | AZ24: 147997.16 | BA24: 147956.66 | BB24: 148417.83 | BC24: 151603.87 | BD24: 155866.59 | BE24: 158079.58 | BF24: 155808.77 | BG24: 155286.77 | BH24: 155705.82 | BI24: 159619.35 | BJ24: 161287.83 | BK24: 163827.32 | BL24: 166692.22 | BM24: 167968.85 | BN24: 174443.81 | BO24: 177137.96 | BP24: 179768.91 | BQ24: 180273.34 | BR24: 181688.3 | BS24: 184767.92 | BT24: 188303.25 | BU24: 191135.39 | BV24: 190221.85 | BW24: 187997.88 | BX24: 188764.07 | BY24: 188394.81 | BZ24: 189057.44 | CA24: 192937.27 | CB24: 197285.66 | CC24: 196885.03 | CD24: 200346.59 | CE24: 205383.08 | CF24: 209305.93 | CG24: 210176.14 | CH24: 209532.55 | CI24: 210845.27 | CJ24: 214972.94 | CK24: 221355.96 | CL24: 228589.54 | CM24: 233836.05 | CN24: 240130.54 | CO24: 251221.71 | CP24: 255363.91 | CQ24: 256618.2 | CR24: 259245.03 | CS24: 260025.67 | CT24: 256748.04 | CU24: 255641.68 | CV24: 262308.3 | CW24: 265699.85 | CX24: 268375.03 | CY24: 272780.87 | CZ24: 279147.45 | DA24: 283102.88 | DB24: 282336.84 | DC24: 283917.06 | DD24: 291666.84 | DE24: 302699.38 | DF24: 313561.74 | DG24: 313897.23 | DH24: 321997.19 | DI24: 329660.37 | DJ24: 339736.72 | DK24: 335140.5 | DL24: 327806.99 | DM24: 310373.64 | DN24: 284385.36 | DO24: 239450.97 | DP24: 264953.26 | DQ24: 286096.23 | DR24: 254628.34 | DS24: 272659.55 | DT24: 318499.17 | DU24: 323940.08 | DV24: 272051.37 | DW24: 278732.92 | DX24: 326999.09 | DY24: 340125.91 | DZ24: 283221.22 | EA24: 285733.39 | EB24: 331700.13 | EC24: 341501.96 | ED24: 286119.99 | EE24: 289370.27 | EF24: 338599.53 | EG24: 348023.59
A25: -
A26: Tasa de variación interanual
A27: Producto Interno Bruto a precios de mercado | F27: 8.6520739 | G27: 7.8543229 | H27: 13.332401 | I27: 7.1753574 | J27: 8.452835 | K27: 7.4206201 | L27: 5.0136835 | M27: 7.5033731 | N27: 3.404016 | O27: 6.9762163 | P27: 4.5768093 | Q27: 3.3249561 | R27: 7.5912456 | S27: 2.8524624 | T27: 2.2480568 | U27: 3.8437285 | V27: -0.38813029 | W27: 0.40036786 | X27: 1.7652945 | Y27: 3.595017 | Z27: 1.8892256 | AA27: 7.4106412 | AB27: 5.1899555 | AC27: 7.4749626 | AD27: 10.856467 | AE27: 5.7291072 | AF27: 6.2515089 | AG27: 5.8516993 | AH27: 2.2954389 | AI27: 5.4566279 | AJ27: 5.2217896 | AK27: 4.0359911 | AL27: 5.7325775 | AM27: 3.484034 | AN27: 3.7868022 | AO27: 2.5308836 | AP27: 3.128195 | AQ27: 3.6724988 | AR27: 4.0227153 | AS27: 3.1867206 | AT27: 1.086564 | AU27: 5.5292821 | AV27: 3.807408 | AW27: 3.3749336 | AX27: 5.2010762 | AY27: 2.877142 | AZ27: 4.3113347 | BA27: 4.8365056 | BB27: 4.5392205 | BC27: 5.0365338 | BD27: 4.0166775 | BE27: 4.1296346 | BF27: 2.391124 | BG27: 4.4323795 | BH27: 4.6097101 | BI27: 4.4848007 | BJ27: 6.5084301 | BK27: 6.1377602 | BL27: 7.6308786 | BM27: 8.9209971 | BN27: 9.0873573 | BO27: 9.3395083 | BP27: 8.1245495 | BQ27: 6.4750293 | BR27: 6.9419689 | BS27: 6.3418124 | BT27: 4.6998142 | BU27: 1.2011629 | BV27: -2.1124707 | BW27: -2.4644714 | BX27: -0.70365015 | BY27: 1.7554305 | BZ27: 5.2138557 | CA27: 5.729604 | CB27: 5.8185733 | CC27: 4.7211336 | CD27: 4.3854433 | CE27: 4.8190536 | CF27: 3.8631317 | CG27: 4.5412305 | CH27: 6.2365847 | CI27: 4.1538569 | CJ27: 4.6355168 | CK27: 4.5079898 | CL27: 1.5346411 | CM27: 2.7994046 | CN27: 3.2537698 | CO27: 2.4238945 | CP27: 4.4445619 | CQ27: 3.1174238 | CR27: 3.1475652 | CS27: 3.4492705 | CT27: 2.0870864 | CU27: 4.6284098 | CV27: 4.8249707 | CW27: 3.1381259 | CX27: 4.5261625 | CY27: 3.8589023 | CZ27: 3.2927218 | DA27: 5.1090141 | DB27: 3.8715332 | DC27: 4.6180361 | DD27: 3.5909315 | DE27: 4.5359705 | DF27: 3.3332281 | DG27: 4.0745659 | DH27: 2.7004103 | DI27: 0.46269153 | DJ27: 2.2793661 | DK27: 0.73954506 | DL27: 2.5439862 | DM27: 4.0844097 | DN27: 1.6392115 | DO27: -8.0121016 | DP27: -6.7520146 | DQ27: -4.0678898 | DR27: -0.99765192 | DS27: 10.315629 | DT27: 12.643915 | DU27: 10.558793 | DV27: 6.6908728 | DW27: 4.2502353 | DX27: 2.7916663 | DY27: 4.5214915 | DZ27: 4.4525056 | EA27: 5.9220004 | EB27: 5.5024024 | EC27: 4.6305536 | ED27: 3.5712756 | EE27: 5.4798299 | EF27: 3.8374041 | EG27: 4.4070205
A28: Impuestos a los productos y las importaciones | F28: 15.965431 | G28: 8.5523668 | H28: 39.034874 | I28: 10.313571 | J28: 31.960467 | K28: 10.702035 | L28: 4.4770436 | M28: 17.30835 | N28: -4.9895711 | O28: 14.846084 | P28: 4.7388042 | Q28: 9.7053576 | R28: 10.698124 | S28: 2.067496 | T28: 4.9896874 | U28: -1.8524532 | V28: 4.3404822 | W28: 8.5083209 | X28: 6.091553 | Y28: 23.879533 | Z28: -5.3678338 | AA28: 12.680978 | AB28: 2.8703628 | AC28: 6.1043734 | AD28: 18.68733 | AE28: 6.0326091 | AF28: 10.169534 | AG28: 4.2882523 | AH28: 2.8123809 | AI28: -6.0058068 | AJ28: -1.7777503 | AK28: -0.6123559 | AL28: 1.0080122 | AM28: 4.1255322 | AN28: 4.6079899 | AO28: 8.3894991 | AP28: 4.6245095 | AQ28: 6.743793 | AR28: 3.3552487 | AS28: 0.05132042 | AT28: 2.5651702 | AU28: 2.3878688 | AV28: 0.8967736 | AW28: 4.8603441 | AX28: 5.3421439 | AY28: 4.0974646 | AZ28: 5.520356 | BA28: 1.5647021 | BB28: 3.5215237 | BC28: 1.3603131 | BD28: 1.0908943 | BE28: 3.0644189 | BF28: 0.99408835 | BG28: 3.7391544 | BH28: 3.8772922 | BI28: 0.16626406 | BJ28: 4.5549275 | BK28: 5.7105231 | BL28: 7.2591364 | BM28: 9.2966656 | BN28: 12.612322 | BO28: 13.034666 | BP28: 14.895095 | BQ28: 9.2240744 | BR28: 12.501907 | BS28: 8.38972 | BT28: 3.0642871 | BU28: -5.8718173 | BV28: -6.8930318 | BW28: -10.254215 | BX28: -7.909523 | BY28: -2.2649548 | BZ28: 1.0528334 | CA28: 5.0003747 | CB28: 7.1769411 | CC28: 7.1090544 | CD28: 6.9570774 | CE28: 11.212838 | CF28: 8.9269518 | CG28: 2.1803042 | CH28: 3.8465123 | CI28: 2.5201108 | CJ28: 1.6511674 | CK28: 1.2052916 | CL28: 0.10194929 | CM28: 3.9895911 | CN28: 4.617519 | CO28: 1.701445 | CP28: 4.5680192 | CQ28: 1.5713404 | CR28: 1.7537726 | CS28: 2.6366364 | CT28: 2.1628319 | CU28: 5.0830525 | CV28: 6.1858537 | CW28: 4.9944051 | CX28: 7.5136619 | CY28: 7.9325677 | CZ28: 6.0864477 | DA28: 4.6167503 | DB28: 3.6687248 | DC28: 1.8814411 | DD28: 1.3997722 | DE28: 1.9680178 | DF28: -0.55170668 | DG28: -0.69017423 | DH28: -0.41059124 | DI28: 0.28818124 | DJ28: -0.52612963 | DK28: -0.5909948 | DL28: 0.77289274 | DM28: 2.0469717 | DN28: 2.3226354 | DO28: -13.657887 | DP28: -11.986604 | DQ28: -21.413047 | DR28: -3.0042895 | DS28: 14.294307 | DT28: 14.520559 | DU28: 47.833686 | DV28: 7.2565886 | DW28: 5.738968 | DX28: 2.5051807 | DY28: 8.6548581 | DZ28: 3.119546 | EA28: 5.9452922 | EB28: 5.8308338 | EC28: 5.589075 | ED28: 5.3013066 | EE28: 9.6436282 | EF28: 2.9885139 | EG28: 3.2380796
A29: Valor agregado a precios básicos (B1b) | F29: 8.0479398 | G29: 7.7964051 | H29: 11.297927 | I29: 6.8824938 | J29: 6.2922479 | K29: 7.1599202 | L29: 5.0507283 | M29: 6.4799429 | N29: 4.3528172 | O29: 6.15336 | P29: 4.5051324 | Q29: 2.8301489 | R29: 7.3189863 | S29: 2.9236887 | T29: 2.0144788 | U29: 4.4089812 | V29: -0.82767285 | W29: -0.28585464 | X29: 1.3750202 | Y29: 1.6111162 | Z29: 2.5707575 | AA29: 6.9055621 | AB29: 5.3882278 | AC29: 7.675036 | AD29: 10.170224 | AE29: 5.7040307 | AF29: 5.8994497 | AG29: 6.0327027 | AH29: 2.2172368 | AI29: 6.4725665 | AJ29: 5.8006453 | AK29: 4.5935633 | AL29: 6.1864806 | AM29: 3.5142074 | AN29: 3.7785196 | AO29: 1.7532403 | AP29: 3.0035938 | AQ29: 3.4327296 | AR29: 4.12735 | AS29: 3.4675305 | AT29: 0.93890673 | AU29: 5.8683046 | AV29: 4.1227374 | AW29: 3.1384737 | AX29: 5.1853329 | AY29: 2.7506246 | AZ29: 4.186074 | BA29: 5.2648405 | BB29: 4.6416565 | BC29: 5.3559441 | BD29: 4.257739 | BE29: 4.3089965 | BF29: 2.5310308 | BG29: 4.5122252 | BH29: 4.6937352 | BI29: 4.9620211 | BJ29: 6.7067502 | BK29: 6.2032547 | BL29: 7.6933945 | BM29: 8.8327725 | BN29: 8.7085471 | BO29: 9.0090267 | BP29: 7.4899131 | BQ29: 6.0755824 | BR29: 6.3124373 | BS29: 6.1394163 | BT29: 4.8841942 | BU29: 2.088317 | BV29: -1.539903 | BW29: -1.6424006 | BX29: 0.04667864 | BY29: 2.2292709 | BZ29: 5.7161817 | CA29: 5.6993804 | CB29: 5.6088758 | CC29: 4.5748714 | CD29: 4.1481403 | CE29: 4.2792478 | CF29: 3.4277959 | CG29: 4.784607 | CH29: 6.4657637 | CI29: 4.3066578 | CJ29: 4.9115358 | CK29: 4.8281292 | CL29: 1.6712875 | CM29: 2.6925408 | CN29: 3.1322643 | CO29: 2.4940482 | CP29: 4.4349426 | CQ29: 3.2525695 | CR29: 3.2678046 | CS29: 3.5277357 | CT29: 2.0840246 | CU29: 4.5858601 | CV29: 4.7044781 | CW29: 2.9735843 | CX29: 4.2664383 | CY29: 3.5094551 | CZ29: 3.0507275 | DA29: 5.1620558 | DB29: 3.8945256 | DC29: 4.8494595 | DD29: 3.7726542 | DE29: 4.762485 | DF29: 3.6783698 | DG29: 4.4555516 | DH29: 2.9463729 | DI29: 0.47741042 | DJ29: 2.5122501 | DK29: 0.83384368 | DL29: 2.6756723 | DM29: 4.2548023 | DN29: 1.5783111 | DO29: -7.5714477 | DP29: -6.3411491 | DQ29: -2.6535993 | DR29: -0.85596303 | DS29: 10.023446 | DT29: 12.50105 | DU29: 8.0326982 | DV29: 6.6400197 | DW29: 4.1538781 | DX29: 2.8389478 | DY29: 4.0739646 | DZ29: 4.5649584 | EA29: 5.9093977 | EB29: 5.4628894 | EC29: 4.5587092 | ED29: 3.4246906 | EE29: 5.1404577 | EF29: 3.8847917 | EG29: 4.5569149
A30: Agricultura, silvicultura y pesca (A) | F30: 3.3177607 | G30: 10.628358 | H30: 7.5541809 | I30: -0.1843244 | J30: 3.3709964 | K30: 1.7120864 | L30: 0.86823673 | M30: 10.280354 | N30: 5.5162299 | O30: 7.1975153 | P30: 10.161472 | Q30: -0.33595201 | R30: 13.643453 | S30: 7.9884298 | T30: 4.7544246 | U30: 11.087159 | V30: -0.95686955 | W30: 1.7549521 | X30: 6.8127626 | Y30: 1.9496337 | Z30: 4.9149165 | AA30: 9.879027 | AB30: 3.5547403 | AC30: 3.3652344 | AD30: 12.259794 | AE30: 4.3000465 | AF30: 6.6537046 | AG30: 8.6249849 | AH30: -0.33684429 | AI30: 10.474628 | AJ30: 1.7447832 | AK30: 3.5684857 | AL30: 7.6558516 | AM30: -6.7350179 | AN30: -1.9952589 | AO30: -4.614511 | AP30: -2.5978206 | AQ30: 3.5938564 | AR30: 3.7749291 | AS30: -1.4756271 | AT30: -6.4292273 | AU30: 1.4343481 | AV30: -0.12477982 | AW30: -4.2266655 | AX30: 4.9292273 | AY30: 2.0720965 | AZ30: 16.172759 | BA30: 8.4510488 | BB30: 3.0813706 | BC30: 6.7323841 | BD30: -4.3572195 | BE30: 3.8984402 | BF30: -1.3912696 | BG30: 4.1792851 | BH30: 4.4360836 | BI30: 1.5105638 | BJ30: 11.909508 | BK30: 3.8906801 | BL30: 8.7714423 | BM30: 12.154167 | BN30: 6.839628 | BO30: 9.1027783 | BP30: 0.97820411 | BQ30: 1.2931303 | BR30: -3.2694339 | BS30: -2.5516935 | BT30: -0.49657835 | BU30: -6.5903124 | BV30: -8.2295577 | BW30: -4.5254646 | BX30: -4.3988751 | BY30: 4.6066252 | BZ30: 9.6107433 | CA30: 6.5564426 | CB30: 8.2920591 | CC30: 0.97183988 | CD30: -1.6713666 | CE30: 1.1179381 | CF30: -0.93017354 | CG30: 0.88367442 | CH30: 8.3644498 | CI30: 0.13534049 | CJ30: 5.8282516 | CK30: 5.6154304 | CL30: -3.1227759 | CM30: -2.0066134 | CN30: 0.58707635 | CO30: 4.9234625 | CP30: 5.652175 | CQ30: 7.4679215 | CR30: -0.05386779 | CS30: -4.0400503 | CT30: -4.7636353 | CU30: -2.137357 | CV30: -2.2237427 | CW30: -0.58571679 | CX30: 5.6075848 | CY30: 4.6561218 | CZ30: 3.3551007 | DA30: 7.4817968 | DB30: 1.5574613 | DC30: 5.1320049 | DD30: 6.4191089 | DE30: 2.0966553 | DF30: 5.299147 | DG30: 6.5159862 | DH30: 2.3710236 | DI30: 1.6138161 | DJ30: -0.07621645 | DK30: -6.7192697 | DL30: 1.6184515 | DM30: -0.16565228 | DN30: 2.489146 | DO30: -3.2504228 | DP30: -2.5243919 | DQ30: -2.4255985 | DR30: -3.6248464 | DS30: 8.349259 | DT30: 2.6739539 | DU30: 2.100191 | DV30: -1.076696 | DW30: -9.8091697 | DX30: 0.00730054 | DY30: 2.1372562 | DZ30: 1.601635 | EA30: 7.2544358 | EB30: 1.4807989 | EC30: 3.6417697 | ED30: 5.0501005 | EE30: -0.8385743 | EF30: 3.3148545 | EG30: 0.395252
A31: Minas y canteras (B) | F31: 24.941356 | G31: 6.2104583 | H31: 21.337672 | I31: 40.715949 | J31: -10.631352 | K31: -13.755157 | L31: -16.558552 | M31: -13.546152 | N31: 13.018598 | O31: 7.7304183 | P31: 8.261256 | Q31: 0.29890583 | R31: 1.618892 | S31: -0.28868576 | T31: -7.1758022 | U31: -14.200926 | V31: -3.485176 | W31: -3.492926 | X31: -9.5171962 | Y31: -0.86740209 | Z31: -7.0107857 | AA31: 13.989764 | AB31: 25.83401 | AC31: 29.607187 | AD31: 18.44975 | AE31: -4.5775173 | AF31: 3.064268 | AG31: 34.04531 | AH31: -2.3565126 | AI31: -6.4619882 | AJ31: -8.7471281 | AK31: -6.902966 | AL31: -1.9180271 | AM31: 0.30930626 | AN31: 8.2978608 | AO31: 16.722934 | AP31: 6.1764611 | AQ31: 7.0989374 | AR31: 17.145789 | AS31: 20.064065 | AT31: 8.7181252 | AU31: 0.02495842 | AV31: -8.1394834 | AW31: -7.4186122 | AX31: 8.1534824 | AY31: 0.52870796 | AZ31: -1.0540181 | BA31: 1.3912603 | BB31: -4.4703227 | BC31: 10.884316 | BD31: 7.5306321 | BE31: 18.970821 | BF31: -12.271373 | BG31: -9.7370435 | BH31: 0.07386756 | BI31: 6.8411746 | BJ31: 8.885175 | BK31: 18.265425 | BL31: 4.5593819 | BM31: 8.7722905 | BN31: 5.9992123 | BO31: 6.3809295 | BP31: 19.253894 | BQ31: -7.0158831 | BR31: 9.6065616 | BS31: 16.668216 | BT31: -0.28036834 | BU31: 3.7910293 | BV31: -13.914268 | BW31: -20.01659 | BX31: -19.810763 | BY31: -13.553897 | BZ31: 0.19315192 | CA31: 9.015651 | CB31: 10.990985 | CC31: 6.2571054 | CD31: -5.1816886 | CE31: -10.211203 | CF31: -11.067733 | CG31: -9.2412403 | CH31: -0.87545994 | CI31: 3.5435845 | CJ31: 7.8281955 | CK31: 7.5722736 | CL31: 7.4469493 | CM31: 10.494584 | CN31: 5.1155682 | CO31: -1.9814404 | CP31: 1.3762018 | CQ31: -10.231868 | CR31: -0.5048741 | CS31: 19.989455 | CT31: -0.35006725 | CU31: 18.503981 | CV31: 16.330119 | CW31: -5.8584037 | CX31: 7.3828677 | CY31: -0.79713068 | CZ31: -2.6941132 | DA31: 18.404741 | DB31: 0.01512764 | DC31: -16.424826 | DD31: -3.884695 | DE31: 2.2783574 | DF31: 11.648596 | DG31: 35.553164 | DH31: 11.160457 | DI31: -1.9895946 | DJ31: -6.9948642 | DK31: -18.813551 | DL31: -20.180127 | DM31: -2.7996119 | DN31: 10.563955 | DO31: -6.5094262 | DP31: 2.248896 | DQ31: 2.7781415 | DR31: 2.7168812 | DS31: 5.8058029 | DT31: -2.5024379 | DU31: -8.3988779 | DV31: -10.112191 | DW31: -4.1238525 | DX31: 4.3953606 | DY31: 9.2938087 | DZ31: 3.9386474 | EA31: 1.9970674 | EB31: 11.209861 | EC31: 11.324634 | ED31: 12.362527 | EE31: 2.6426309 | EF31: -0.07768608 | EG31: -4.0084523
A32: Manufactura (C) | F32: 13.39908 | G32: 8.1973358 | H32: 17.585221 | I32: 1.9406996 | J32: 6.1948574 | K32: 7.1919895 | L32: 2.0304434 | M32: 5.2980416 | N32: 0.21994494 | O32: 5.8798675 | P32: 1.394918 | Q32: 0.46687941 | R32: 10.719672 | S32: -1.8014224 | T32: -2.5282852 | U32: 6.781059 | V32: -1.9416105 | W32: -2.6678359 | X32: 0.61016813 | Y32: 1.6599281 | Z32: 1.8229986 | AA32: 13.791892 | AB32: 6.9984949 | AC32: 8.5962857 | AD32: 14.955391 | AE32: 2.2636863 | AF32: 0.67091252 | AG32: 4.9644132 | AH32: -3.6622249 | AI32: 4.2931287 | AJ32: 7.1336353 | AK32: 2.2628661 | AL32: 8.1910751 | AM32: 6.4116813 | AN32: 3.4663859 | AO32: -4.340079 | AP32: -1.0043057 | AQ32: -1.1510393 | AR32: 1.8501421 | AS32: -1.7455443 | AT32: -5.3446234 | AU32: 10.176231 | AV32: 5.248819 | AW32: 5.1511165 | AX32: 6.1638474 | AY32: -1.4752419 | AZ32: -3.0912266 | BA32: 3.6222371 | BB32: 2.7894743 | BC32: 4.6021811 | BD32: 4.8404323 | BE32: 3.9946567 | BF32: 1.1005565 | BG32: 4.2004743 | BH32: 4.6093936 | BI32: 4.5742485 | BJ32: 3.476693 | BK32: 1.2260772 | BL32: 4.2523713 | BM32: 6.9708183 | BN32: 6.3600587 | BO32: 4.5011244 | BP32: 2.6376152 | BQ32: -1.6449685 | BR32: 1.1048315 | BS32: 0.59493837 | BT32: -2.3407986 | BU32: -8.2085535 | BV32: -11.726323 | BW32: -13.300936 | BX32: -5.6513506 | BY32: -0.8473313 | BZ32: 8.5288419 | CA32: 7.4968851 | CB32: 6.7516801 | CC32: 4.6916171 | CD32: 3.1699476 | CE32: 4.5770425 | CF32: 1.4895334 | CG32: 5.7165814 | CH32: 6.446995 | CI32: 2.461731 | CJ32: 1.9962892 | CK32: 5.1232404 | CL32: -3.403467 | CM32: 2.1362379 | CN32: 2.9950438 | CO32: -1.2914775 | CP32: 3.4052504 | CQ32: -0.18689904 | CR32: -1.4108583 | CS32: -0.95157327 | CT32: -5.8950344 | CU32: -4.1295844 | CV32: -2.7381848 | CW32: -3.4363972 | CX32: 3.2933289 | CY32: 5.8571304 | CZ32: 4.3296376 | DA32: 3.685248 | DB32: 3.6375992 | DC32: 2.6359384 | DD32: 4.9857912 | DE32: 4.5423483 | DF32: 2.767116 | DG32: 6.8876077 | DH32: 4.2077537 | DI32: 3.1974196 | DJ32: 2.7226243 | DK32: 1.8318811 | DL32: 2.9691876 | DM32: 4.4154567 | DN32: 6.9290531 | DO32: -9.2764583 | DP32: 1.5435965 | DQ32: 8.4560923 | DR32: 8.0152264 | DS32: 32.805235 | DT32: 22.167476 | DU32: 12.804107 | DV32: 6.4297427 | DW32: 0.57697199 | DX32: 3.3926884 | DY32: 3.1860299 | DZ32: 8.751602 | EA32: 11.288664 | EB32: 5.0858407 | EC32: 8.6117078 | ED32: 2.0557904 | EE32: 7.5608616 | EF32: 6.0688997 | EG32: 6.2015137
A33: Electricidad, agua y servicios de saneamiento (D, E) | F33: 9.2322418 | G33: 6.3701712 | H33: 8.1741832 | I33: 5.6536874 | J33: 3.9539 | K33: 3.7817106 | L33: 1.7183857 | M33: 4.0790232 | N33: 5.8379967 | O33: 8.0652613 | P33: 8.9549252 | Q33: 7.4767097 | R33: 7.7672173 | S33: 3.8361265 | T33: 1.6816958 | U33: 2.7737504 | V33: 1.8168184 | W33: 4.3995566 | X33: 4.8412083 | Y33: 4.8868754 | Z33: 4.6588602 | AA33: 6.5702787 | AB33: 7.8781939 | AC33: 9.7688511 | AD33: 12.029588 | AE33: 10.669782 | AF33: 10.267896 | AG33: 9.6884685 | AH33: 8.6023808 | AI33: 9.884171 | AJ33: 10.18098 | AK33: 8.7531426 | AL33: 7.4655171 | AM33: 6.2094707 | AN33: 5.0022802 | AO33: 5.7007159 | AP33: 4.4690438 | AQ33: 4.245165 | AR33: 3.7429335 | AS33: 1.8118842 | AT33: 3.8087931 | AU33: 5.2020678 | AV33: 4.8623349 | AW33: 4.8404108 | AX33: 6.5260359 | AY33: 4.6230815 | AZ33: 3.7603435 | BA33: 4.9013671 | BB33: 3.245957 | BC33: 3.5039888 | BD33: 4.3486626 | BE33: 3.363232 | BF33: 4.4585418 | BG33: 5.8331784 | BH33: 5.6722516 | BI33: 5.3671388 | BJ33: 6.105461 | BK33: 4.8199314 | BL33: 5.2760907 | BM33: 5.2581467 | BN33: 4.6109033 | BO33: 2.7872615 | BP33: 2.8612117 | BQ33: 1.6380233 | BR33: -0.25183154 | BS33: 0.19442167 | BT33: -1.1075714 | BU33: -0.45953554 | BV33: 0.46513325 | BW33: 2.3893025 | BX33: 4.0611248 | BY33: 3.6509065 | BZ33: 4.4250055 | CA33: 3.7606934 | CB33: 0.86595025 | CC33: -0.03488897 | CD33: -0.30806961 | CE33: 2.4685513 | CF33: 3.8023931 | CG33: 7.5101755 | CH33: 10.532463 | CI33: 8.6582307 | CJ33: 6.636541 | CK33: -2.1002473 | CL33: -9.9412577 | CM33: -15.286442 | CN33: -17.622137 | CO33: -13.229086 | CP33: -3.7875996 | CQ33: 2.1850263 | CR33: 7.3787173 | CS33: 9.2862973 | CT33: 7.7268195 | CU33: 10.920066 | CV33: 12.850325 | CW33: 12.306299 | CX33: 9.8394452 | CY33: 7.4362166 | CZ33: 2.5476771 | DA33: 1.8871878 | DB33: 2.5849108 | DC33: 3.3581979 | DD33: 7.5108414 | DE33: 5.9569235 | DF33: 1.3889575 | DG33: 0.52434773 | DH33: -2.7920274 | DI33: -2.8025113 | DJ33: 0.09032497 | DK33: -0.54558577 | DL33: 1.6012436 | DM33: 5.1628219 | DN33: 11.201115 | DO33: 3.8079731 | DP33: 6.7156942 | DQ33: 5.2693774 | DR33: -2.4172229 | DS33: 4.3420316 | DT33: 1.5709821 | DU33: 1.1493154 | DV33: 3.428337 | DW33: 7.4082498 | DX33: 7.320151 | DY33: 5.7130935 | DZ33: 3.5829811 | EA33: 0.41081826 | EB33: -0.82467591 | EC33: -0.82295422 | ED33: -1.6705414 | EE33: -0.77325283 | EF33: -3.4633946 | EG33: -2.041265
A34: Construcción (F) | F34: 27.042161 | G34: 11.258053 | H34: 23.837705 | I34: 13.616022 | J34: 16.48089 | K34: 23.656745 | L34: 9.7531721 | M34: 9.0654476 | N34: 6.3233619 | O34: 3.4555838 | P34: 8.8452941 | Q34: 15.864583 | R34: 17.902678 | S34: 9.2950397 | T34: 9.4279516 | U34: -1.1077371 | V34: -18.349592 | W34: -20.37357 | X34: -20.333678 | Y34: -15.542504 | Z34: -6.7843198 | AA34: 2.8644539 | AB34: 4.3087525 | AC34: 28.820346 | AD34: 36.193968 | AE34: 18.005345 | AF34: 23.337304 | AG34: 2.5011809 | AH34: -7.8632654 | AI34: 6.0977277 | AJ34: 3.3922147 | AK34: -1.0089751 | AL34: 1.2641357 | AM34: 3.046615 | AN34: 5.7131901 | AO34: 8.1011956 | AP34: 10.087251 | AQ34: 11.214218 | AR34: 23.042302 | AS34: 25.852195 | AT34: 13.714324 | AU34: 3.2031756 | AV34: -8.3744889 | AW34: -8.3420301 | AX34: 11.942126 | AY34: 4.4388665 | AZ34: 3.5536551 | BA34: 4.5055932 | BB34: -2.0464654 | BC34: 8.4045353 | BD34: 13.133244 | BE34: 8.0989965 | BF34: 3.2762553 | BG34: -2.1619735 | BH34: 1.5466221 | BI34: 1.7900953 | BJ34: 9.2315683 | BK34: 15.567265 | BL34: 14.597225 | BM34: 14.375468 | BN34: 20.002183 | BO34: 30.800418 | BP34: 21.364114 | BQ34: 16.396458 | BR34: 15.298688 | BS34: 10.08263 | BT34: 6.9905045 | BU34: 9.6989291 | BV34: -0.93113242 | BW34: -1.0219985 | BX34: -1.953802 | BY34: -3.7791102 | BZ34: -4.3784878 | CA34: -5.6069818 | CB34: -5.9879391 | CC34: -4.6011518 | CD34: -1.9480236 | CE34: 0.57524075 | CF34: 3.1875951 | CG34: 4.3041649 | CH34: 10.422688 | CI34: 1.524542 | CJ34: 2.0801128 | CK34: -4.9223394 | CL34: -12.779512 | CM34: -5.9511964 | CN34: -1.5903121 | CO34: -8.7840316 | CP34: 1.3574404 | CQ34: -12.480778 | CR34: 0.50443745 | CS34: 17.429197 | CT34: 3.3371205 | CU34: 29.680189 | CV34: 14.893016 | CW34: -9.2366553 | CX34: -2.8356688 | CY34: -14.690306 | CZ34: -8.2145147 | DA34: 22.697565 | DB34: 9.1335999 | DC34: 11.526401 | DD34: -25.111679 | DE34: -7.7603234 | DF34: -14.455239 | DG34: 3.7383173 | DH34: 22.150862 | DI34: -6.2817114 | DJ34: -0.38425994 | DK34: -17.421727 | DL34: -16.639399 | DM34: -0.01342134 | DN34: -6.6429437 | DO34: 14.194339 | DP34: 0.0501593 | DQ34: -9.6949882 | DR34: -2.5192908 | DS34: -4.2904633 | DT34: 17.753498 | DU34: 3.0265856 | DV34: 18.5149 | DW34: -15.285999 | DX34: -20.841524 | DY34: 2.0505725 | DZ34: -2.4586752 | EA34: 19.115724 | EB34: 41.355661 | EC34: 2.2201986 | ED34: -2.5635272 | EE34: 10.435358 | EF34: -8.984404 | EG34: 16.17032
A35: Comercio al por mayor y al por menor (G) | F35: 10.269537 | G35: 7.5507468 | H35: 11.203562 | I35: 12.457387 | J35: 6.2161996 | K35: 7.3468248 | L35: 6.8011559 | M35: 4.6124289 | N35: 1.1115367 | O35: 4.5403837 | P35: 0.57369331 | Q35: 1.5002347 | R35: 2.6293596 | S35: -0.59951603 | T35: -0.277587 | U35: -0.27620131 | V35: -7.6980066 | W35: -6.9933906 | X35: -2.6884533 | Y35: 1.7070821 | Z35: -2.149698 | AA35: 4.0074495 | AB35: 5.8766023 | AC35: 7.6540915 | AD35: 9.0376299 | AE35: 6.1355007 | AF35: 2.7620864 | AG35: -0.82468764 | AH35: -2.8187216 | AI35: -3.2675029 | AJ35: -2.7581687 | AK35: -0.93916503 | AL35: -1.3055177 | AM35: -1.7566841 | AN35: -0.20217911 | AO35: 2.4715088 | AP35: 4.5910478 | AQ35: 2.8974998 | AR35: -0.09001855 | AS35: 4.6148969 | AT35: -1.043139 | AU35: 4.5423186 | AV35: 4.7117469 | AW35: 3.5195922 | AX35: 3.5744727 | AY35: -0.05424123 | AZ35: 3.2710598 | BA35: 3.5292353 | BB35: 6.233632 | BC35: 3.3459842 | BD35: 0.66933333 | BE35: -1.1668441 | BF35: -3.4880844 | BG35: 1.7209548 | BH35: 3.2549355 | BI35: 5.8620578 | BJ35: 7.8120952 | BK35: 8.117359 | BL35: 8.3527967 | BM35: 8.0005311 | BN35: 8.8625756 | BO35: 8.4119091 | BP35: 7.4305909 | BQ35: 9.7240341 | BR35: 7.1533966 | BS35: 9.3396304 | BT35: 6.6948042 | BU35: -0.28375588 | BV35: -5.5551062 | BW35: -8.1156708 | BX35: -6.6696551 | BY35: -2.0817688 | BZ35: 3.7787462 | CA35: 7.3974928 | CB35: 5.6801775 | CC35: 8.449705 | CD35: 7.5764788 | CE35: 6.0765031 | CF35: 3.85599 | CG35: 4.8175831 | CH35: 5.5930326 | CI35: 3.5099815 | CJ35: 4.0611486 | CK35: 3.3606798 | CL35: 4.3554675 | CM35: 5.3597253 | CN35: 6.7379692 | CO35: 5.0434729 | CP35: 5.1539946 | CQ35: 3.8184703 | CR35: 2.2232814 | CS35: 3.0902742 | CT35: 3.9882034 | CU35: 3.6537858 | CV35: 5.5176495 | CW35: 3.8470474 | CX35: 2.186584 | CY35: 4.7830992 | CZ35: 4.1904876 | DA35: 5.1909783 | DB35: 7.11632 | DC35: 7.3840007 | DD35: 8.1895668 | DE35: 5.3010661 | DF35: 4.1677361 | DG35: 4.0143403 | DH35: 0.88790879 | DI35: 0.06765044 | DJ35: -0.14434845 | DK35: -1.259749 | DL35: -0.05489863 | DM35: 2.8866333 | DN35: 0.80949849 | DO35: -13.186542 | DP35: -11.789633 | DQ35: -7.3492215 | DR35: 2.2628527 | DS35: 12.646292 | DT35: 11.585974 | DU35: 7.1944608 | DV35: 4.6295555 | DW35: 4.2438539 | DX35: 1.9723468 | DY35: 2.2286456 | DZ35: 1.3639248 | EA35: 2.3606009 | EB35: 4.4773279 | EC35: 5.904903 | ED35: 4.4147491 | EE35: 5.3234034 | EF35: 3.5439896 | EG35: 2.6165286
