Workbook

Sheet Data
A1: Fecha | B1: TBP | C1: TPM | D1: Tipo de Cambio
A2: 40179 | B2: {=+SUMIFS(OFFSET(TBP!$A:$A,,MATCH(YEAR(A2),VALUE(TBP!$5:$5),0)-1),TBP!$AV:$AV,DAY(A2),TBP!$AW:$AW,MONTH(A2))/100} -> 0.0825 | C2: {=+SUMIFS(OFFSET(TPM!$A:$A,,MATCH(YEAR(A2),VALUE(TPM!$5:$5),0)-1),TPM!$W:$W,DAY(A2),TPM!$X:$X,MONTH(A2))/100} -> 0.09 | D2: =+INDEX(TC!$C:$C,MATCH(A2,TC!$E:$E,0)) -> 571.81
A3: =+A2+1 -> 40180 | B3: {=+SUMIFS(OFFSET(TBP!$A:$A,,MATCH(YEAR(A3),VALUE(TBP!$5:$5),0)-1),TBP!$AV:$AV,DAY(A3),TBP!$AW:$AW,MONTH(A3))/100} -> 0.0825 | C3: {=+SUMIFS(OFFSET(TPM!$A:$A,,MATCH(YEAR(A3),VALUE(TPM!$5:$5),0)-1),TPM!$W:$W,DAY(A3),TPM!$X:$X,MONTH(A3))/100} -> 0.09 | D3: =+INDEX(TC!$C:$C,MATCH(A3,TC!$E:$E,0)) -> 571.81
A4: =+A3+1 -> 40181 | B4: {=+SUMIFS(OFFSET(TBP!$A:$A,,MATCH(YEAR(A4),VALUE(TBP!$5:$5),0)-1),TBP!$AV:$AV,DAY(A4),TBP!$AW:$AW,MONTH(A4))/100} -> 0.0825 | C4: {=+SUMIFS(OFFSET(TPM!$A:$A,,MATCH(YEAR(A4),VALUE(TPM!$5:$5),0)-1),TPM!$W:$W,DAY(A4),TPM!$X:$X,MONTH(A4))/100} -> 0.09 | D4: =+INDEX(TC!$C:$C,MATCH(A4,TC!$E:$E,0)) -> 571.81
A5: =+A4+1 -> 40182 | B5: {=+SUMIFS(OFFSET(TBP!$A:$A,,MATCH(YEAR(A5),VALUE(TBP!$5:$5),0)-1),TBP!$AV:$AV,DAY(A5),TBP!$AW:$AW,MONTH(A5))/100} -> 0.0825 | C5: {=+SUMIFS(OFFSET(TPM!$A:$A,,MATCH(YEAR(A5),VALUE(TPM!$5:$5),0)-1),TPM!$W:$W,DAY(A5),TPM!$X:$X,MONTH(A5))/100} -> 0.09 | D5: =+INDEX(TC!$C:$C,MATCH(A5,TC!$E:$E,0)) -> 571.81
A6: =+A5+1 -> 40183 | B6: {=+SUMIFS(OFFSET(TBP!$A:$A,,MATCH(YEAR(A6),VALUE(TBP!$5:$5),0)-1),TBP!$AV:$AV,DAY(A6),TBP!$AW:$AW,MONTH(A6))/100} -> 0.0825 | C6: {=+SUMIFS(OFFSET(TPM!$A:$A,,MATCH(YEAR(A6),VALUE(TPM!$5:$5),0)-1),TPM!$W:$W,DAY(A6),TPM!$X:$X,MONTH(A6))/100} -> 0.09 | D6: =+INDEX(TC!$C:$C,MATCH(A6,TC!$E:$E,0)) -> 568.02
A7: =+A6+1 -> 40184 | B7: {=+SUMIFS(OFFSET(TBP!$A:$A,,MATCH(YEAR(A7),VALUE(TBP!$5:$5),0)-1),TBP!$AV:$AV,DAY(A7),TBP!$AW:$AW,MONTH(A7))/100} -> 0.0825 | C7: {=+SUMIFS(OFFSET(TPM!$A:$A,,MATCH(YEAR(A7),VALUE(TPM!$5:$5),0)-1),TPM!$W:$W,DAY(A7),TPM!$X:$X,MONTH(A7))/100} -> 0.09 | D7: =+INDEX(TC!$C:$C,MATCH(A7,TC!$E:$E,0)) -> 569.69
A8: =+A7+1 -> 40185 | B8: {=+SUMIFS(OFFSET(TBP!$A:$A,,MATCH(YEAR(A8),VALUE(TBP!$5:$5),0)-1),TBP!$AV:$AV,DAY(A8),TBP!$AW:$AW,MONTH(A8))/100} -> 0.08 | C8: {=+SUMIFS(OFFSET(TPM!$A:$A,,MATCH(YEAR(A8),VALUE(TPM!$5:$5),0)-1),TPM!$W:$W,DAY(A8),TPM!$X:$X,MONTH(A8))/100} -> 0.09 | D8: =+INDEX(TC!$C:$C,MATCH(A8,TC!$E:$E,0)) -> 574.52
A9: =+A8+1 -> 40186 | B9: {=+SUMIFS(OFFSET(TBP!$A:$A,,MATCH(YEAR(A9),VALUE(TBP!$5:$5),0)-1),TBP!$AV:$AV,DAY(A9),TBP!$AW:$AW,MONTH(A9))/100} -> 0.08 | C9: {=+SUMIFS(OFFSET(TPM!$A:$A,,MATCH(YEAR(A9),VALUE(TPM!$5:$5),0)-1),TPM!$W:$W,DAY(A9),TPM!$X:$X,MONTH(A9))/100} -> 0.09 | D9: =+INDEX(TC!$C:$C,MATCH(A9,TC!$E:$E,0)) -> 580.56
A10: =+A9+1 -> 40187 | B10: {=+SUMIFS(OFFSET(TBP!$A:$A,,MATCH(YEAR(A10),VALUE(TBP!$5:$5),0)-1),TBP!$AV:$AV,DAY(A10),TBP!$AW:$AW,MONTH(A10))/100} -> 0.08 | C10: {=+SUMIFS(OFFSET(TPM!$A:$A,,MATCH(YEAR(A10),VALUE(TPM!$5:$5),0)-1),TPM!$W:$W,DAY(A10),TPM!$X:$X,MONTH(A10))/100} -> 0.09 | D10: =+INDEX(TC!$C:$C,MATCH(A10,TC!$E:$E,0)) -> 582.21
A11: =+A10+1 -> 40188 | B11: {=+SUMIFS(OFFSET(TBP!$A:$A,,MATCH(YEAR(A11),VALUE(TBP!$5:$5),0)-1),TBP!$AV:$AV,DAY(A11),TBP!$AW:$AW,MONTH(A11))/100} -> 0.08 | C11: {=+SUMIFS(OFFSET(TPM!$A:$A,,MATCH(YEAR(A11),VALUE(TPM!$5:$5),0)-1),TPM!$W:$W,DAY(A11),TPM!$X:$X,MONTH(A11))/100} -> 0.09 | D11: =+INDEX(TC!$C:$C,MATCH(A11,TC!$E:$E,0)) -> 582.21
A12: =+A11+1 -> 40189 | B12: {=+SUMIFS(OFFSET(TBP!$A:$A,,MATCH(YEAR(A12),VALUE(TBP!$5:$5),0)-1),TBP!$AV:$AV,DAY(A12),TBP!$AW:$AW,MONTH(A12))/100} -> 0.08 | C12: {=+SUMIFS(OFFSET(TPM!$A:$A,,MATCH(YEAR(A12),VALUE(TPM!$5:$5),0)-1),TPM!$W:$W,DAY(A12),TPM!$X:$X,MONTH(A12))/100} -> 0.09 | D12: =+INDEX(TC!$C:$C,MATCH(A12,TC!$E:$E,0)) -> 582.21
A13: =+A12+1 -> 40190 | B13: {=+SUMIFS(OFFSET(TBP!$A:$A,,MATCH(YEAR(A13),VALUE(TBP!$5:$5),0)-1),TBP!$AV:$AV,DAY(A13),TBP!$AW:$AW,MONTH(A13))/100} -> 0.08 | C13: {=+SUMIFS(OFFSET(TPM!$A:$A,,MATCH(YEAR(A13),VALUE(TPM!$5:$5),0)-1),TPM!$W:$W,DAY(A13),TPM!$X:$X,MONTH(A13))/100} -> 0.09 | D13: =+INDEX(TC!$C:$C,MATCH(A13,TC!$E:$E,0)) -> 577.9
A14: =+A13+1 -> 40191 | B14: {=+SUMIFS(OFFSET(TBP!$A:$A,,MATCH(YEAR(A14),VALUE(TBP!$5:$5),0)-1),TBP!$AV:$AV,DAY(A14),TBP!$AW:$AW,MONTH(A14))/100} -> 0.08 | C14: {=+SUMIFS(OFFSET(TPM!$A:$A,,MATCH(YEAR(A14),VALUE(TPM!$5:$5),0)-1),TPM!$W:$W,DAY(A14),TPM!$X:$X,MONTH(A14))/100} -> 0.09 | D14: =+INDEX(TC!$C:$C,MATCH(A14,TC!$E:$E,0)) -> 574.78
... A5509: =+A5508+1 -> 45686 | B5509: {=+SUMIFS(OFFSET(TBP!$A:$A,,MATCH(YEAR(A5509),VALUE(TBP!$5:$5),0)-1),TBP!$AV:$AV,DAY(A5509),TBP!$AW:$AW,MONTH(A5509))/100} -> 0.0413 | C5509: {=+SUMIFS(OFFSET(TPM!$A:$A,,MATCH(YEAR(A5509),VALUE(TPM!$5:$5),0)-1),TPM!$W:$W,DAY(A5509),TPM!$X:$X,MONTH(A5509))/100} -> 0.04 | D5509: =+INDEX(TC!$C:$C,MATCH(A5509,TC!$E:$E,0)) -> 509.26

Sheet TBP
A1: Tasa Básica Pasiva (TBP)
A2: Diaria
A3: En porcentajes
B5: 1981 | C5: 1982 | D5: 1983 | E5: 1984 | F5: 1985 | G5: 1986 | H5: 1987 | I5: 1988 | J5: 1989 | K5: 1990 | L5: 1991 | M5: 1992 | N5: 1993 | O5: 1994 | P5: 1995 | Q5: 1996 | R5: 1997 | S5: 1998 | T5: 1999 | U5: 2000 | V5: 2001 | W5: 2002 | X5: 2003 | Y5: 2004 | Z5: 2005 | AA5: 2006 | AB5: 2007 | AC5: 2008 | AD5: 2009 | AE5: 2010 | AF5: 2011 | AG5: 2012 | AH5: 2013 | AI5: 2014 | AJ5: 2015 | AK5: 2016 | AL5: 2017 | AM5: 2018 | AN5: 2019 | AO5: 2020 | AP5: 2021 | AQ5: 2022 | AR5: 2023 | AS5: 2024 | AT5: 2025 | AV5: Día | AW5: Mes
A6: 1 Ene | C6: 21.5 | D6: 25 | E6: 22 | F6: 20 | G6: 20 | H6: 20 | I6: 23.5 | J6: 23.5 | K6: 23.5 | L6: 34 | M6: 29.5 | N6: 19.5 | O6: 25 | P6: 27.75 | Q6: 28.5 | R6: 24.6 | S6: 18.5 | T6: 24.5 | U6: 18.25 | V6: 15.5 | W6: 16 | X6: 17.5 | Y6: 13.75 | Z6: 14.25 | AA6: 15.25 | AB6: 11.25 | AC6: 7 | AD6: 11.5 | AE6: 8.25 | AF6: 8 | AG6: 8 | AH6: 9.2 | AI6: 6.5 | AJ6: 7.2 | AK6: 5.95 | AL6: 4.45 | AM6: 5.95 | AN6: 6 | AO6: 5.75 | AP6: 3.5 | AQ6: 2.9 | AR6: 6.35 | AS6: 5.36 | AT6: 4.13 | AV6: =LEFT(A6,FIND(" ",A6)) -> 1 | AW6: =MATCH(MID(A6,LEN(AV6)+1,3),Sheet4!$A$1:$A$12,0) -> 1
A7: 2 Ene | C7: 21.5 | D7: 25 | E7: 22 | F7: 20 | G7: 20 | H7: 20 | I7: 23.5 | J7: 23.5 | K7: 23.5 | L7: 34 | M7: 29.5 | N7: 19.5 | O7: 25 | P7: 27.75 | Q7: 28.5 | R7: 24.6 | S7: 18.5 | T7: 24.5 | U7: 18.25 | V7: 15.5 | W7: 16 | X7: 17.5 | Y7: 13.75 | Z7: 14.25 | AA7: 15.25 | AB7: 11.25 | AC7: 7 | AD7: 11.5 | AE7: 8.25 | AF7: 8 | AG7: 8 | AH7: 9.2 | AI7: 6.5 | AJ7: 7.2 | AK7: 5.95 | AL7: 4.45 | AM7: 5.95 | AN7: 6 | AO7: 5.75 | AP7: 3.5 | AQ7: 2.9 | AR7: 6.35 | AS7: 5.36 | AT7: 4.15 | AV7: =LEFT(A7,FIND(" ",A7)) -> 2 | AW7: =MATCH(MID(A7,LEN(AV7)+1,3),Sheet4!$A$1:$A$12,0) -> 1
A8: 3 Ene | C8: 21.5 | D8: 25 | E8: 22 | F8: 20 | G8: 20 | H8: 20 | I8: 23.5 | J8: 23.5 | K8: 23.5 | L8: 34 | M8: 29.5 | N8: 19.5 | O8: 25 | P8: 27.75 | Q8: 28.5 | R8: 24.6 | S8: 18.5 | T8: 24.5 | U8: 18.25 | V8: 15.5 | W8: 16 | X8: 17.5 | Y8: 13.75 | Z8: 14.25 | AA8: 15.25 | AB8: 11.25 | AC8: 7 | AD8: 11.5 | AE8: 8.25 | AF8: 8 | AG8: 8 | AH8: 9.1 | AI8: 6.5 | AJ8: 7.2 | AK8: 5.95 | AL8: 4.45 | AM8: 5.95 | AN8: 6 | AO8: 5.75 | AP8: 3.5 | AQ8: 2.9 | AR8: 6.35 | AS8: 5.36 | AT8: 4.15 | AV8: =LEFT(A8,FIND(" ",A8)) -> 3 | AW8: =MATCH(MID(A8,LEN(AV8)+1,3),Sheet4!$A$1:$A$12,0) -> 1
A9: 4 Ene | C9: 21.5 | D9: 25 | E9: 22 | F9: 20 | G9: 20 | H9: 20 | I9: 23.5 | J9: 23.5 | K9: 23.5 | L9: 34 | M9: 29.5 | N9: 19.5 | O9: 25 | P9: 27.75 | Q9: 28.5 | R9: 24.6 | S9: 18.5 | T9: 24.5 | U9: 18.25 | V9: 15.5 | W9: 16 | X9: 17.5 | Y9: 13.75 | Z9: 14.25 | AA9: 15.25 | AB9: 11 | AC9: 7 | AD9: 11.5 | AE9: 8.25 | AF9: 8 | AG9: 8 | AH9: 9.1 | AI9: 6.5 | AJ9: 7.2 | AK9: 5.95 | AL9: 4.45 | AM9: 5.9 | AN9: 6 | AO9: 5.75 | AP9: 3.5 | AQ9: 2.9 | AR9: 6.35 | AS9: 5.34 | AT9: 4.15 | AV9: =LEFT(A9,FIND(" ",A9)) -> 4 | AW9: =MATCH(MID(A9,LEN(AV9)+1,3),Sheet4!$A$1:$A$12,0) -> 1
A10: 5 Ene | C10: 21.5 | D10: 25 | E10: 22 | F10: 20 | G10: 20 | H10: 20 | I10: 23.5 | J10: 23.5 | K10: 23.5 | L10: 34 | M10: 29.5 | N10: 19.5 | O10: 25 | P10: 27.75 | Q10: 28.5 | R10: 24.6 | S10: 18.5 | T10: 24.5 | U10: 18.25 | V10: 15.5 | W10: 16 | X10: 17.5 | Y10: 13.75 | Z10: 14.25 | AA10: 15.25 | AB10: 11 | AC10: 7 | AD10: 11.5 | AE10: 8.25 | AF10: 8 | AG10: 8 | AH10: 9.1 | AI10: 6.5 | AJ10: 7.2 | AK10: 5.95 | AL10: 4.35 | AM10: 5.9 | AN10: 6 | AO10: 5.75 | AP10: 3.5 | AQ10: 2.9 | AR10: 6.35 | AS10: 5.34 | AT10: 4.15 | AV10: =LEFT(A10,FIND(" ",A10)) -> 5 | AW10: =MATCH(MID(A10,LEN(AV10)+1,3),Sheet4!$A$1:$A$12,0) -> 1
A11: 6 Ene | C11: 21.5 | D11: 25 | E11: 22 | F11: 20 | G11: 20 | H11: 20 | I11: 23.5 | J11: 23.5 | K11: 23.5 | L11: 34 | M11: 29.5 | N11: 19.5 | O11: 25 | P11: 27.75 | Q11: 28.5 | R11: 24.6 | S11: 18.5 | T11: 24.5 | U11: 18 | V11: 15.5 | W11: 16 | X11: 17.5 | Y11: 13.75 | Z11: 14.25 | AA11: 15.25 | AB11: 11 | AC11: 7 | AD11: 11.5 | AE11: 8.25 | AF11: 7.25 | AG11: 8 | AH11: 9.1 | AI11: 6.5 | AJ11: 7.2 | AK11: 5.95 | AL11: 4.35 | AM11: 5.9 | AN11: 6 | AO11: 5.75 | AP11: 3.5 | AQ11: 2.9 | AR11: 6.35 | AS11: 5.34 | AT11: 4.15 | AV11: =LEFT(A11,FIND(" ",A11)) -> 6 | AW11: =MATCH(MID(A11,LEN(AV11)+1,3),Sheet4!$A$1:$A$12,0) -> 1
A12: 7 Ene | C12: 21.5 | D12: 25 | E12: 22 | F12: 20 | G12: 20 | H12: 20 | I12: 23.5 | J12: 23.5 | K12: 23.5 | L12: 34 | M12: 29.5 | N12: 19.5 | O12: 24.75 | P12: 27.75 | Q12: 28.5 | R12: 24.6 | S12: 18.5 | T12: 24.5 | U12: 18 | V12: 15.5 | W12: 16 | X12: 17.5 | Y12: 13.75 | Z12: 14.25 | AA12: 15.25 | AB12: 11 | AC12: 7 | AD12: 11.5 | AE12: 8 | AF12: 7.25 | AG12: 8 | AH12: 9.1 | AI12: 6.5 | AJ12: 7.2 | AK12: 5.95 | AL12: 4.35 | AM12: 5.9 | AN12: 6 | AO12: 5.75 | AP12: 3.4 | AQ12: 2.9 | AR12: 6.35 | AS12: 5.34 | AT12: 4.15 | AV12: =LEFT(A12,FIND(" ",A12)) -> 7 | AW12: =MATCH(MID(A12,LEN(AV12)+1,3),Sheet4!$A$1:$A$12,0) -> 1
A13: 8 Ene | C13: 21.5 | D13: 25 | E13: 22 | F13: 20 | G13: 20 | H13: 20 | I13: 23.5 | J13: 23.5 | K13: 23.5 | L13: 34 | M13: 29.5 | N13: 19.5 | O13: 24.75 | P13: 27.75 | Q13: 28.5 | R13: 24.6 | S13: 18.5 | T13: 24.5 | U13: 18 | V13: 15.5 | W13: 16 | X13: 17.5 | Y13: 13.75 | Z13: 14.25 | AA13: 15.25 | AB13: 11 | AC13: 7 | AD13: 11.75 | AE13: 8 | AF13: 7.25 | AG13: 8 | AH13: 9.1 | AI13: 6.5 | AJ13: 7.25 | AK13: 5.95 | AL13: 4.35 | AM13: 5.9 | AN13: 6 | AO13: 5.75 | AP13: 3.4 | AQ13: 2.9 | AR13: 6.35 | AS13: 5.34 | AT13: 4.15 | AV13: =LEFT(A13,FIND(" ",A13)) -> 8 | AW13: =MATCH(MID(A13,LEN(AV13)+1,3),Sheet4!$A$1:$A$12,0) -> 1
A14: 9 Ene | C14: 21.5 | D14: 25 | E14: 22 | F14: 20 | G14: 20 | H14: 20 | I14: 23.5 | J14: 23.5 | K14: 23.5 | L14: 34 | M14: 29.5 | N14: 19.5 | O14: 24.75 | P14: 27.75 | Q14: 28.5 | R14: 24.7 | S14: 18.5 | T14: 24.5 | U14: 18 | V14: 15.5 | W14: 16 | X14: 17.5 | Y14: 13.75 | Z14: 14.25 | AA14: 15.25 | AB14: 11 | AC14: 7 | AD14: 11.75 | AE14: 8 | AF14: 7.25 | AG14: 8 | AH14: 9.1 | AI14: 6.55 | AJ14: 7.25 | AK14: 5.95 | AL14: 4.35 | AM14: 5.9 | AN14: 6 | AO14: 5.7 | AP14: 3.4 | AQ14: 2.9 | AR14: 6.35 | AS14: 5.34 | AT14: 4.14 | AV14: =LEFT(A14,FIND(" ",A14)) -> 9 | AW14: =MATCH(MID(A14,LEN(AV14)+1,3),Sheet4!$A$1:$A$12,0) -> 1
A15: 10 Ene | C15: 21.5 | D15: 25 | E15: 22 | F15: 20 | G15: 20 | H15: 20 | I15: 23.5 | J15: 23.5 | K15: 23.5 | L15: 34 | M15: 29.5 | N15: 19.5 | O15: 24.75 | P15: 27.75 | Q15: 28.5 | R15: 24.7 | S15: 18.5 | T15: 24.5 | U15: 18 | V15: 15.5 | W15: 16.25 | X15: 17.5 | Y15: 13.75 | Z15: 14.25 | AA15: 15.25 | AB15: 11 | AC15: 7.25 | AD15: 11.75 | AE15: 8 | AF15: 7.25 | AG15: 8 | AH15: 9.05 | AI15: 6.55 | AJ15: 7.25 | AK15: 5.95 | AL15: 4.35 | AM15: 5.9 | AN15: 6.05 | AO15: 5.7 | AP15: 3.4 | AQ15: 2.9 | AR15: 6.35 | AS15: 5.34 | AT15: 4.14 | AV15: =LEFT(A15,FIND(" ",A15)) -> 10 | AW15: =MATCH(MID(A15,LEN(AV15)+1,3),Sheet4!$A$1:$A$12,0) -> 1
A16: 11 Ene | C16: 21.5 | D16: 25 | E16: 22 | F16: 20 | G16: 20 | H16: 20 | I16: 23.5 | J16: 23.5 | K16: 23.5 | L16: 34 | M16: 29.5 | N16: 19.5 | O16: 24.75 | P16: 27.75 | Q16: 28.5 | R16: 24.7 | S16: 18.5 | T16: 24.5 | U16: 18 | V16: 15.5 | W16: 16.25 | X16: 17.5 | Y16: 13.75 | Z16: 14.25 | AA16: 15.25 | AB16: 11 | AC16: 7.25 | AD16: 11.75 | AE16: 8 | AF16: 7.25 | AG16: 8 | AH16: 9.05 | AI16: 6.55 | AJ16: 7.25 | AK16: 5.95 | AL16: 4.35 | AM16: 6 | AN16: 6.05 | AO16: 5.7 | AP16: 3.4 | AQ16: 2.9 | AR16: 6.35 | AS16: 5.33 | AT16: 4.14 | AV16: =LEFT(A16,FIND(" ",A16)) -> 11 | AW16: =MATCH(MID(A16,LEN(AV16)+1,3),Sheet4!$A$1:$A$12,0) -> 1
A17: 12 Ene | C17: 21.5 | D17: 25 | E17: 22 | F17: 20 | G17: 20 | H17: 20 | I17: 23.5 | J17: 23.5 | K17: 23.5 | L17: 34 | M17: 29.5 | N17: 19.5 | O17: 24.75 | P17: 27.75 | Q17: 28.5 | R17: 24.7 | S17: 18.5 | T17: 24.5 | U17: 18 | V17: 15.5 | W17: 16.25 | X17: 17.5 | Y17: 13.75 | Z17: 14.25 | AA17: 15.25 | AB17: 11 | AC17: 7.25 | AD17: 11.75 | AE17: 8 | AF17: 7.25 | AG17: 8.5 | AH17: 9.05 | AI17: 6.55 | AJ17: 7.25 | AK17: 5.95 | AL17: 4.55 | AM17: 6 | AN17: 6.05 | AO17: 5.7 | AP17: 3.4 | AQ17: 2.9 | AR17: 6.41 | AS17: 5.33 | AT17: 4.14 | AV17: =LEFT(A17,FIND(" ",A17)) -> 12 | AW17: =MATCH(MID(A17,LEN(AV17)+1,3),Sheet4!$A$1:$A$12,0) -> 1
... A41: 5 Feb | C41: 21.5 | D41: 25 | E41: 18 | F41: 20 | G41: 20 | H41: 19.5 | I41: 23.5 | J41: 23.5 | K41: 23.5 | L41: 35 | M41: 27.5 | N41: 19 | O41: 23.75 | P41: 27.75 | Q41: 27.25 | R41: 24.6 | S41: 18.25 | T41: 24.5 | U41: 17.5 | V41: 15.5 | W41: 16.25 | X41: 17.5 | Y41: 13.5 | Z41: 14.75 | AA41: 15.25 | AB41: 10.75 | AC41: 7.25 | AD41: 11.25 | AE41: 8 | AF41: 7.5 | AG41: 8.75 | AH41: 8.3 | AI41: 6.55 | AJ41: 7.25 | AK41: 5.95 | AL41: 4.6 | AM41: 6.05 | AN41: 6.25 | AO41: 5.75 | AP41: 3.5 | AQ41: 3 | AR41: 6.58 | AS41: 5.21 | AT41: 4.09 | AV41: =LEFT(A41,FIND(" ",A41)) -> 5 | AW41: =MATCH(MID(A41,LEN(AV41)+1,3),Sheet4!$A$1:$A$12,0) -> 2
A42: 6 Feb | C42: 21.5 | D42: 25 | E42: 18 | F42: 20 | G42: 20 | H42: 19.5 | I42: 23.5 | J42: 23.5 | K42: 23.5 | L42: 35 | M42: 27.5 | N42: 19 | O42: 23.75 | P42: 27.75 | Q42: 27.25 | R42: 24.5 | S42: 18.25 | T42: 24.5 | U42: 17.5 | V42: 15.5 | W42: 16.25 | X42: 17.25 | Y42: 13.5 | Z42: 14.75 | AA42: 15.25 | AB42: 10.75 | AC42: 7.25 | AD42: 11.25 | AE42: 8 | AF42: 7.5 | AG42: 8.75 | AH42: 8.3 | AI42: 6.55 | AJ42: 7.25 | AK42: 5.95 | AL42: 4.6 | AM42: 6.05 | AN42: 6.25 | AO42: 5.75 | AP42: 3.5 | AQ42: 3 | AR42: 6.58 | AS42: 5.21 | AV42: =LEFT(A42,FIND(" ",A42)) -> 6 | AW42: =MATCH(MID(A42,LEN(AV42)+1,3),Sheet4!$A$1:$A$12,0) -> 2
A43: 7 Feb | C43: 21.5 | D43: 25 | E43: 18 | F43: 20 | G43: 20 | H43: 19.5 | I43: 23.5 | J43: 23.5 | K43: 23.5 | L43: 35 | M43: 27.5 | N43: 19 | O43: 23.75 | P43: 27.75 | Q43: 27.25 | R43: 24.5 | S43: 18.25 | T43: 24.5 | U43: 17.5 | V43: 15.5 | W43: 16.25 | X43: 17.25 | Y43: 13.5 | Z43: 14.75 | AA43: 15.25 | AB43: 10.75 | AC43: 6.5 | AD43: 11.25 | AE43: 8 | AF43: 7.5 | AG43: 8.75 | AH43: 8.05 | AI43: 6.55 | AJ43: 7.25 | AK43: 5.95 | AL43: 4.6 | AM43: 6.05 | AN43: 6.15 | AO43: 5.75 | AP43: 3.5 | AQ43: 3 | AR43: 6.58 | AS43: 5.21 | AV43: =LEFT(A43,FIND(" ",A43)) -> 7 | AW43: =MATCH(MID(A43,LEN(AV43)+1,3),Sheet4!$A$1:$A$12,0) -> 2
A44: 8 Feb | C44: 21.5 | D44: 25 | E44: 18 | F44: 20 | G44: 20 | H44: 19.5 | I44: 23.5 | J44: 23.5 | K44: 23.5 | L44: 35 | M44: 27.5 | N44: 19 | O44: 23.75 | P44: 27.75 | Q44: 27.25 | R44: 24.5 | S44: 18.25 | T44: 24.5 | U44: 17.5 | V44: 15.5 | W44: 16.25 | X44: 17.25 | Y44: 13.5 | Z44: 14.75 | AA44: 15.25 | AB44: 10.25 | AC44: 6.5 | AD44: 11.25 | AE44: 8 | AF44: 7.5 | AG44: 8.75 | AH44: 8.05 | AI44: 6.55 | AJ44: 7.25 | AK44: 5.95 | AL44: 4.6 | AM44: 6 | AN44: 6.15 | AO44: 5.75 | AP44: 3.5 | AQ44: 3 | AR44: 6.58 | AS44: 5.17 | AV44: =LEFT(A44,FIND(" ",A44)) -> 8 | AW44: =MATCH(MID(A44,LEN(AV44)+1,3),Sheet4!$A$1:$A$12,0) -> 2
A45: 9 Feb | C45: 21.5 | D45: 25 | E45: 18 | F45: 20 | G45: 20 | H45: 19.5 | I45: 23.5 | J45: 23.5 | K45: 23.5 | L45: 35 | M45: 27.5 | N45: 19 | O45: 23.75 | P45: 27.75 | Q45: 27.25 | R45: 24.5 | S45: 18.25 | T45: 24.5 | U45: 17.5 | V45: 15.5 | W45: 16.25 | X45: 17.25 | Y45: 13.5 | Z45: 14.75 | AA45: 15.25 | AB45: 10.25 | AC45: 6.5 | AD45: 11.25 | AE45: 8 | AF45: 7.5 | AG45: 9 | AH45: 8.05 | AI45: 6.55 | AJ45: 7.25 | AK45: 5.95 | AL45: 4.5 | AM45: 6 | AN45: 6.15 | AO45: 5.75 | AP45: 3.5 | AQ45: 3 | AR45: 6.59 | AS45: 5.17 | AV45: =LEFT(A45,FIND(" ",A45)) -> 9 | AW45: =MATCH(MID(A45,LEN(AV45)+1,3),Sheet4!$A$1:$A$12,0) -> 2
A46: 10 Feb | C46: 21.5 | D46: 25 | E46: 18 | F46: 20 | G46: 20 | H46: 19.5 | I46: 23.5 | J46: 23.5 | K46: 23.5 | L46: 35 | M46: 27.5 | N46: 19 | O46: 23.25 | P46: 27.75 | Q46: 27.25 | R46: 24.5 | S46: 18.25 | T46: 24.5 | U46: 17.5 | V46: 15.5 | W46: 16.25 | X46: 17.25 | Y46: 13.5 | Z46: 14.75 | AA46: 15.25 | AB46: 10.25 | AC46: 6.5 | AD46: 11.25 | AE46: 8 | AF46: 7.5 | AG46: 9 | AH46: 8.05 | AI46: 6.55 | AJ46: 7.25 | AK46: 5.95 | AL46: 4.5 | AM46: 6 | AN46: 6.15 | AO46: 5.75 | AP46: 3.5 | AQ46: 3.05 | AR46: 6.59 | AS46: 5.17 | AV46: =LEFT(A46,FIND(" ",A46)) -> 10 | AW46: =MATCH(MID(A46,LEN(AV46)+1,3),Sheet4!$A$1:$A$12,0) -> 2
A47: 11 Feb | C47: 21.5 | D47: 25 | E47: 18 | F47: 20 | G47: 20 | H47: 19.5 | I47: 23.5 | J47: 23.5 | K47: 23.5 | L47: 35 | M47: 27.5 | N47: 19 | O47: 23.25 | P47: 27.75 | Q47: 27.25 | R47: 24.5 | S47: 18.25 | T47: 24.5 | U47: 17.5 | V47: 15.5 | W47: 16.25 | X47: 17.25 | Y47: 13.5 | Z47: 14.75 | AA47: 15.25 | AB47: 10.25 | AC47: 6.5 | AD47: 11.25 | AE47: 8 | AF47: 7.5 | AG47: 9 | AH47: 8.05 | AI47: 6.55 | AJ47: 7.25 | AK47: 5.9 | AL47: 4.5 | AM47: 6 | AN47: 6.15 | AO47: 5.75 | AP47: 3.5 | AQ47: 3.05 | AR47: 6.59 | AS47: 5.17 | AV47: =LEFT(A47,FIND(" ",A47)) -> 11 | AW47: =MATCH(MID(A47,LEN(AV47)+1,3),Sheet4!$A$1:$A$12,0) -> 2
A48: 12 Feb | C48: 21.5 | D48: 25 | E48: 18 | F48: 20 | G48: 20 | H48: 19.5 | I48: 23.5 | J48: 23.5 | K48: 23.5 | L48: 35 | M48: 27.5 | N48: 19 | O48: 23.25 | P48: 27.75 | Q48: 27.25 | R48: 24.5 | S48: 18.25 | T48: 24.5 | U48: 17.5 | V48: 15.5 | W48: 16.25 | X48: 17.25 | Y48: 13.5 | Z48: 14.75 | AA48: 15.25 | AB48: 10.25 | AC48: 6.5 | AD48: 12 | AE48: 8 | AF48: 7.5 | AG48: 9 | AH48: 8.05 | AI48: 6.55 | AJ48: 7.15 | AK48: 5.9 | AL48: 4.5 | AM48: 6 | AN48: 6.15 | AO48: 5.75 | AP48: 3.5 | AQ48: 3.05 | AR48: 6.59 | AS48: 5.17 | AV48: =LEFT(A48,FIND(" ",A48)) -> 12 | AW48: =MATCH(MID(A48,LEN(AV48)+1,3),Sheet4!$A$1:$A$12,0) -> 2
A49: 13 Feb | C49: 21.5 | D49: 25 | E49: 18 | F49: 20 | G49: 20 | H49: 19.5 | I49: 23.5 | J49: 23.5 | K49: 23.5 | L49: 35 | M49: 27.5 | N49: 19 | O49: 23.25 | P49: 27.75 | Q49: 27.25 | R49: 24.25 | S49: 18.25 | T49: 24.5 | U49: 17.5 | V49: 15.5 | W49: 16.25 | X49: 17.25 | Y49: 13.5 | Z49: 14.75 | AA49: 15.25 | AB49: 10.25 | AC49: 6.5 | AD49: 12 | AE49: 8 | AF49: 7.5 | AG49: 9 | AH49: 8.05 | AI49: 6.5 | AJ49: 7.15 | AK49: 5.9 | AL49: 4.5 | AM49: 6 | AN49: 6.15 | AO49: 5.65 | AP49: 3.5 | AQ49: 3.05 | AR49: 6.59 | AS49: 5.17 | AV49: =LEFT(A49,FIND(" ",A49)) -> 13 | AW49: =MATCH(MID(A49,LEN(AV49)+1,3),Sheet4!$A$1:$A$12,0) -> 2
A50: 14 Feb | C50: 21.5 | D50: 25 | E50: 18 | F50: 20 | G50: 20 | H50: 19.5 | I50: 23.5 | J50: 23.5 | K50: 23.5 | L50: 35 | M50: 27.5 | N50: 19 | O50: 23.25 | P50: 27.75 | Q50: 27.25 | R50: 24.25 | S50: 18.25 | T50: 24.5 | U50: 17.5 | V50: 15.5 | W50: 16.25 | X50: 17.25 | Y50: 13.5 | Z50: 14.75 | AA50: 15.25 | AB50: 10.25 | AC50: 5.75 | AD50: 12 | AE50: 8 | AF50: 7.5 | AG50: 9 | AH50: 7.8 | AI50: 6.5 | AJ50: 7.15 | AK50: 5.9 | AL50: 4.5 | AM50: 6 | AN50: 6.2 | AO50: 5.65 | AP50: 3.5 | AQ50: 3.05 | AR50: 6.59 | AS50: 5.17 | AV50: =LEFT(A50,FIND(" ",A50)) -> 14 | AW50: =MATCH(MID(A50,LEN(AV50)+1,3),Sheet4!$A$1:$A$12,0) -> 2
A51: 15 Feb | C51: 21.5 | D51: 25 | E51: 18 | F51: 20 | G51: 20 | H51: 19.5 | I51: 23.5 | J51: 23.5 | K51: 23.5 | L51: 35 | M51: 27.5 | N51: 19 | O51: 23.25 | P51: 27.75 | Q51: 27.25 | R51: 24.25 | S51: 18.25 | T51: 24.5 | U51: 17.5 | V51: 15.25 | W51: 16.25 | X51: 17.25 | Y51: 13.5 | Z51: 14.75 | AA51: 15.25 | AB51: 9.75 | AC51: 5.75 | AD51: 12 | AE51: 8 | AF51: 7.5 | AG51: 9 | AH51: 7.8 | AI51: 6.5 | AJ51: 7.15 | AK51: 5.9 | AL51: 4.5 | AM51: 6.05 | AN51: 6.2 | AO51: 5.65 | AP51: 3.5 | AQ51: 3.05 | AR51: 6.59 | AS51: 5.12 | AV51: =LEFT(A51,FIND(" ",A51)) -> 15 | AW51: =MATCH(MID(A51,LEN(AV51)+1,3),Sheet4!$A$1:$A$12,0) -> 2
A52: 16 Feb | C52: 21.5 | D52: 25 | E52: 18 | F52: 20 | G52: 20 | H52: 19.5 | I52: 23.5 | J52: 23.5 | K52: 23.5 | L52: 35 | M52: 27.5 | N52: 19 | O52: 23.25 | P52: 28.25 | Q52: 27.25 | R52: 24.25 | S52: 18.25 | T52: 24.5 | U52: 17.5 | V52: 15.25 | W52: 16.25 | X52: 17.25 | Y52: 13.5 | Z52: 14.75 | AA52: 15.25 | AB52: 9.75 | AC52: 5.75 | AD52: 12 | AE52: 8 | AF52: 7.5 | AG52: 8.75 | AH52: 7.8 | AI52: 6.5 | AJ52: 7.15 | AK52: 5.9 | AL52: 4.55 | AM52: 6.05 | AN52: 6.2 | AO52: 5.65 | AP52: 3.5 | AQ52: 3.05 | AR52: 6.61 | AS52: 5.12 | AV52: =LEFT(A52,FIND(" ",A52)) -> 16 | AW52: =MATCH(MID(A52,LEN(AV52)+1,3),Sheet4!$A$1:$A$12,0) -> 2
A53: 17 Feb | C53: 21.5 | D53: 25 | E53: 18 | F53: 20 | G53: 20 | H53: 19.5 | I53: 23.5 | J53: 23.5 | K53: 23.5 | L53: 35 | M53: 27.5 | N53: 19 | O53: 23.25 | P53: 28.25 | Q53: 27.25 | R53: 24.25 | S53: 18.25 | T53: 24.5 | U53: 17.5 | V53: 15.25 | W53: 16.25 | X53: 17.25 | Y53: 13.5 | Z53: 14.75 | AA53: 15.25 | AB53: 9.75 | AC53: 5.75 | AD53: 12 | AE53: 8 | AF53: 7.5 | AG53: 8.75 | AH53: 7.8 | AI53: 6.5 | AJ53: 7.15 | AK53: 5.9 | AL53: 4.55 | AM53: 6.05 | AN53: 6.2 | AO53: 5.65 | AP53: 3.5 | AQ53: 3.05 | AR53: 6.61 | AS53: 5.12 | AV53: =LEFT(A53,FIND(" ",A53)) -> 17 | AW53: =MATCH(MID(A53,LEN(AV53)+1,3),Sheet4!$A$1:$A$12,0) -> 2
... A64: 28 Feb | C64: 21.5 | D64: 25 | E64: 18 | F64: 20 | G64: 20 | H64: 19.5 | I64: 23.5 | J64: 23.5 | K64: 23.5 | L64: 35 | M64: 27.5 | N64: 19 | O64: 23.25 | P64: 29.25 | Q64: 27.25 | R64: 24 | S64: 18.25 | T64: 24.5 | U64: 17.5 | V64: 15.25 | W64: 16.75 | X64: 17.25 | Y64: 13.5 | Z64: 14.75 | AA64: 15.25 | AB64: 9.75 | AC64: 5.5 | AD64: 12 | AE64: 8 | AF64: 7.5 | AG64: 9 | AH64: 7.35 | AI64: 6.5 | AJ64: 7.15 | AK64: 5.7 | AL64: 4.6 | AM64: 6 | AN64: 6.25 | AO64: 4.8 | AP64: 3.45 | AQ64: 3.05 | AR64: 6.69 | AS64: 5.07 | AV64: =LEFT(A64,FIND(" ",A64)) -> 28 | AW64: =MATCH(MID(A64,LEN(AV64)+1,3),Sheet4!$A$1:$A$12,0) -> 2
A65: 29 Feb | E65: 18 | I65: 23.5 | M65: 27.5 | Q65: 26.5 | U65: 17.5 | Y65: 13.5 | AC65: 5.5 | AG65: 9 | AK65: 5.7 | AO65: 4.8 | AS65: 5.04 | AV65: =LEFT(A65,FIND(" ",A65)) -> 29 | AW65: =MATCH(MID(A65,LEN(AV65)+1,3),Sheet4!$A$1:$A$12,0) -> 2
A66: 1 Mar | C66: 21.5 | D66: 25 | E66: 18 | F66: 20 | G66: 20 | H66: 19.5 | I66: 23.5 | J66: 23 | K66: 23.5 | L66: 35 | M66: 26 | N66: 19 | O66: 23.25 | P66: 29.25 | Q66: 26.5 | R66: 24 | S66: 18.25 | T66: 24.5 | U66: 17.5 | V66: 15 | W66: 16.75 | X66: 17.25 | Y66: 13.5 | Z66: 14.75 | AA66: 15.25 | AB66: 9.25 | AC66: 5.5 | AD66: 12 | AE66: 8 | AF66: 7.5 | AG66: 9.25 | AH66: 7.35 | AI66: 6.5 | AJ66: 7.15 | AK66: 5.7 | AL66: 4.6 | AM66: 6.1 | AN66: 6.25 | AO66: 4.8 | AP66: 3.45 | AQ66: 3.05 | AR66: 6.69 | AS66: 5.04 | AV66: =LEFT(A66,FIND(" ",A66)) -> 1 | AW66: =MATCH(MID(A66,LEN(AV66)+1,3),Sheet4!$A$1:$A$12,0) -> 3
A67: 2 Mar | C67: 21.5 | D67: 25 | E67: 18 | F67: 20 | G67: 20 | H67: 19.5 | I67: 23.5 | J67: 23 | K67: 23.5 | L67: 35 | M67: 26 | N67: 19 | O67: 23.25 | P67: 30 | Q67: 26.5 | R67: 24 | S67: 18.25 | T67: 24.5 | U67: 17.25 | V67: 15 | W67: 16.75 | X67: 17.25 | Y67: 13.5 | Z67: 14.75 | AA67: 15.25 | AB67: 9.25 | AC67: 5.5 | AD67: 12 | AE67: 8 | AF67: 7.5 | AG67: 9.25 | AH67: 7.35 | AI67: 6.5 | AJ67: 7.15 | AK67: 5.7 | AL67: 4.6 | AM67: 6.1 | AN67: 6.25 | AO67: 4.8 | AP67: 3.45 | AQ67: 3.05 | AR67: 6.72 | AS67: 5.04 | AV67: =LEFT(A67,FIND(" ",A67)) -> 2 | AW67: =MATCH(MID(A67,LEN(AV67)+1,3),Sheet4!$A$1:$A$12,0) -> 3
A68: 3 Mar | C68: 21.5 | D68: 25 | E68: 18 | F68: 20 | G68: 20 | H68: 19.5 | I68: 23.5 | J68: 23 | K68: 23.5 | L68: 35 | M68: 26 | N68: 19 | O68: 23.25 | P68: 30 | Q68: 26.5 | R68: 24 | S68: 18.25 | T68: 24.5 | U68: 17.25 | V68: 15 | W68: 16.75 | X68: 17.25 | Y68: 13.5 | Z68: 14.75 | AA68: 15.25 | AB68: 9.25 | AC68: 5.5 | AD68: 12 | AE68: 8 | AF68: 7.25 | AG68: 9.25 | AH68: 7.35 | AI68: 6.5 | AJ68: 7.15 | AK68: 5.6 | AL68: 4.6 | AM68: 6.1 | AN68: 6.25 | AO68: 4.8 | AP68: 3.45 | AQ68: 3 | AR68: 6.72 | AS68: 5.04 | AV68: =LEFT(A68,FIND(" ",A68)) -> 3 | AW68: =MATCH(MID(A68,LEN(AV68)+1,3),Sheet4!$A$1:$A$12,0) -> 3
A69: 4 Mar | C69: 21.5 | D69: 25 | E69: 18 | F69: 20 | G69: 20 | H69: 19.5 | I69: 23.5 | J69: 23 | K69: 23.5 | L69: 33 | M69: 26 | N69: 19 | O69: 23.25 | P69: 30 | Q69: 26.5 | R69: 24 | S69: 18.25 | T69: 24.5 | U69: 17.25 | V69: 15 | W69: 16.75 | X69: 17.25 | Y69: 13.5 | Z69: 14.75 | AA69: 15.25 | AB69: 9.25 | AC69: 5.5 | AD69: 12 | AE69: 8.25 | AF69: 7.25 | AG69: 9.25 | AH69: 7.35 | AI69: 6.5 | AJ69: 7.15 | AK69: 5.6 | AL69: 4.6 | AM69: 6.1 | AN69: 6.25 | AO69: 4.8 | AP69: 3.45 | AQ69: 3 | AR69: 6.72 | AS69: 5.04 | AV69: =LEFT(A69,FIND(" ",A69)) -> 4 | AW69: =MATCH(MID(A69,LEN(AV69)+1,3),Sheet4!$A$1:$A$12,0) -> 3
A70: 5 Mar | C70: 21.5 | D70: 25 | E70: 18 | F70: 20 | G70: 20 | H70: 19.5 | I70: 23.5 | J70: 23 | K70: 23.5 | L70: 33 | M70: 26 | N70: 19 | O70: 23.25 | P70: 30 | Q70: 26.5 | R70: 24 | S70: 18.25 | T70: 24.5 | U70: 17.25 | V70: 15 | W70: 16.75 | X70: 17.25 | Y70: 13.5 | Z70: 14.75 | AA70: 15.25 | AB70: 9.25 | AC70: 5.5 | AD70: 12 | AE70: 8.25 | AF70: 7.25 | AG70: 9.25 | AH70: 7.35 | AI70: 6.5 | AJ70: 7.15 | AK70: 5.6 | AL70: 4.6 | AM70: 6.1 | AN70: 6.25 | AO70: 4.5 | AP70: 3.45 | AQ70: 3 | AR70: 6.72 | AS70: 5.04 | AV70: =LEFT(A70,FIND(" ",A70)) -> 5 | AW70: =MATCH(MID(A70,LEN(AV70)+1,3),Sheet4!$A$1:$A$12,0) -> 3
A71: 6 Mar | C71: 21.5 | D71: 25 | E71: 18 | F71: 20 | G71: 20 | H71: 19.5 | I71: 23.5 | J71: 23 | K71: 23.5 | L71: 33 | M71: 26 | N71: 19 | O71: 23.25 | P71: 30 | Q71: 26.5 | R71: 23.5 | S71: 18.25 | T71: 24.5 | U71: 17.25 | V71: 15 | W71: 16.75 | X71: 17.25 | Y71: 13.5 | Z71: 14.75 | AA71: 15.25 | AB71: 9.25 | AC71: 5.5 | AD71: 12 | AE71: 8.25 | AF71: 7.25 | AG71: 9.25 | AH71: 7.35 | AI71: 6.45 | AJ71: 7.15 | AK71: 5.6 | AL71: 4.6 | AM71: 6.1 | AN71: 6.25 | AO71: 4.5 | AP71: 3.45 | AQ71: 3 | AR71: 6.72 | AS71: 5.04 | AV71: =LEFT(A71,FIND(" ",A71)) -> 6 | AW71: =MATCH(MID(A71,LEN(AV71)+1,3),Sheet4!$A$1:$A$12,0) -> 3
A72: 7 Mar | C72: 21.5 | D72: 25 | E72: 18 | F72: 20 | G72: 20 | H72: 19.5 | I72: 23.5 | J72: 23 | K72: 23.5 | L72: 33 | M72: 26 | N72: 19 | O72: 23.25 | P72: 30 | Q72: 25.6 | R72: 23.5 | S72: 18.25 | T72: 24.5 | U72: 17.25 | V72: 15 | W72: 16.75 | X72: 17.25 | Y72: 13.5 | Z72: 14.75 | AA72: 15.25 | AB72: 9.25 | AC72: 5.5 | AD72: 12 | AE72: 8.25 | AF72: 7.25 | AG72: 9.25 | AH72: 7.25 | AI72: 6.45 | AJ72: 7.15 | AK72: 5.6 | AL72: 4.6 | AM72: 6.1 | AN72: 6.15 | AO72: 4.5 | AP72: 3.45 | AQ72: 3 | AR72: 6.72 | AS72: 5.01 | AV72: =LEFT(A72,FIND(" ",A72)) -> 7 | AW72: =MATCH(MID(A72,LEN(AV72)+1,3),Sheet4!$A$1:$A$12,0) -> 3
A73: 8 Mar | C73: 21.5 | D73: 25 | E73: 18 | F73: 20 | G73: 20 | H73: 19.5 | I73: 23.5 | J73: 23 | K73: 23.5 | L73: 33 | M73: 26 | N73: 19 | O73: 23.25 | P73: 30 | Q73: 25.6 | R73: 23.5 | S73: 18.25 | T73: 24.5 | U73: 17.25 | V73: 15 | W73: 16.75 | X73: 17.25 | Y73: 13.5 | Z73: 14.75 | AA73: 15.25 | AB73: 8.75 | AC73: 5.5 | AD73: 12 | AE73: 8.25 | AF73: 7.25 | AG73: 9.25 | AH73: 7.25 | AI73: 6.45 | AJ73: 7.15 | AK73: 5.6 | AL73: 4.6 | AM73: 5.95 | AN73: 6.15 | AO73: 4.5 | AP73: 3.45 | AQ73: 3 | AR73: 6.72 | AS73: 5.01 | AV73: =LEFT(A73,FIND(" ",A73)) -> 8 | AW73: =MATCH(MID(A73,LEN(AV73)+1,3),Sheet4!$A$1:$A$12,0) -> 3
A74: 9 Mar | C74: 21.5 | D74: 25 | E74: 18 | F74: 20 | G74: 20 | H74: 19.5 | I74: 23.5 | J74: 23 | K74: 23.5 | L74: 33 | M74: 26 | N74: 19 | O74: 23.25 | P74: 30 | Q74: 25.6 | R74: 23.5 | S74: 18.25 | T74: 24.5 | U74: 17.25 | V74: 15 | W74: 16.75 | X74: 17.25 | Y74: 13.5 | Z74: 14.75 | AA74: 15.25 | AB74: 8.75 | AC74: 5.5 | AD74: 12 | AE74: 8.25 | AF74: 7.25 | AG74: 9.25 | AH74: 7.25 | AI74: 6.45 | AJ74: 7.15 | AK74: 5.6 | AL74: 4.55 | AM74: 5.95 | AN74: 6.15 | AO74: 4.5 | AP74: 3.45 | AQ74: 3 | AR74: 6.71 | AS74: 5.01 | AV74: =LEFT(A74,FIND(" ",A74)) -> 9 | AW74: =MATCH(MID(A74,LEN(AV74)+1,3),Sheet4!$A$1:$A$12,0) -> 3
...

Sheet TPM
A1: Tasa de política monetaria
A2: Para operaciones en moneda nacional del Banco Central de Costa Rica (BCCR)
B5: 2006 | C5: 2007 | D5: 2008 | E5: 2009 | F5: 2010 | G5: 2011 | H5: 2012 | I5: 2013 | J5: 2014 | K5: 2015 | L5: 2016 | M5: 2017 | N5: 2018 | O5: 2019 | P5: 2020 | Q5: 2021 | R5: 2022 | S5: 2023 | T5: 2024 | U5: 2025 | W5: Día | X5: Mes
A6: 1 Ene | E6: 10 | F6: 9 | G6: 6.5 | H6: 5 | I6: 5 | J6: 3.75 | K6: 5.25 | L6: 2.25 | M6: 1.75 | N6: 4.75 | O6: 5.25 | P6: 2.75 | Q6: 0.75 | R6: 1.25 | S6: 9 | T6: 6 | U6: 4 | W6: =LEFT(A6,FIND(" ",A6)) -> 1 | X6: =MATCH(MID(A6,LEN(W6)+1,3),Sheet4!$A$1:$A$12,0) -> 1
A7: 2 Ene | C7: 8.97 | D7: 5.52 | E7: 10 | F7: 9 | G7: 6.5 | H7: 5 | I7: 5 | J7: 3.75 | K7: 5.25 | L7: 2.25 | M7: 1.75 | N7: 4.75 | O7: 5.25 | P7: 2.75 | Q7: 0.75 | R7: 1.25 | S7: 9 | T7: 6 | U7: 4 | W7: =LEFT(A7,FIND(" ",A7)) -> 2 | X7: =MATCH(MID(A7,LEN(W7)+1,3),Sheet4!$A$1:$A$12,0) -> 1
A8: 3 Ene | C8: 8.97 | D8: 5.52 | E8: 10 | F8: 9 | G8: 6.5 | H8: 5 | I8: 5 | J8: 3.75 | K8: 5.25 | L8: 2.25 | M8: 1.75 | N8: 4.75 | O8: 5.25 | P8: 2.75 | Q8: 0.75 | R8: 1.25 | S8: 9 | T8: 6 | U8: 4 | W8: =LEFT(A8,FIND(" ",A8)) -> 3 | X8: =MATCH(MID(A8,LEN(W8)+1,3),Sheet4!$A$1:$A$12,0) -> 1
A9: 4 Ene | C9: 8.97 | D9: 5.52 | E9: 10 | F9: 9 | G9: 6.5 | H9: 5 | I9: 5 | J9: 3.75 | K9: 5.25 | L9: 1.75 | M9: 1.75 | N9: 4.75 | O9: 5.25 | P9: 2.75 | Q9: 0.75 | R9: 1.25 | S9: 9 | T9: 6 | U9: 4 | W9: =LEFT(A9,FIND(" ",A9)) -> 4 | X9: =MATCH(MID(A9,LEN(W9)+1,3),Sheet4!$A$1:$A$12,0) -> 1
A10: 5 Ene | C10: 8.97 | E10: 10 | F10: 9 | G10: 6.5 | H10: 5 | I10: 5 | J10: 3.75 | K10: 5.25 | L10: 1.75 | M10: 1.75 | N10: 4.75 | O10: 5.25 | P10: 2.75 | Q10: 0.75 | R10: 1.25 | S10: 9 | T10: 6 | U10: 4 | W10: =LEFT(A10,FIND(" ",A10)) -> 5 | X10: =MATCH(MID(A10,LEN(W10)+1,3),Sheet4!$A$1:$A$12,0) -> 1
A11: 6 Ene | E11: 10 | F11: 9 | G11: 6.5 | H11: 5 | I11: 5 | J11: 3.75 | K11: 5.25 | L11: 1.75 | M11: 1.75 | N11: 4.75 | O11: 5.25 | P11: 2.75 | Q11: 0.75 | R11: 1.25 | S11: 9 | T11: 6 | U11: 4 | W11: =LEFT(A11,FIND(" ",A11)) -> 6 | X11: =MATCH(MID(A11,LEN(W11)+1,3),Sheet4!$A$1:$A$12,0) -> 1
A12: 7 Ene | D12: 5.52 | E12: 10 | F12: 9 | G12: 6.5 | H12: 5 | I12: 5 | J12: 3.75 | K12: 5.25 | L12: 1.75 | M12: 1.75 | N12: 4.75 | O12: 5.25 | P12: 2.75 | Q12: 0.75 | R12: 1.25 | S12: 9 | T12: 6 | U12: 4 | W12: =LEFT(A12,FIND(" ",A12)) -> 7 | X12: =MATCH(MID(A12,LEN(W12)+1,3),Sheet4!$A$1:$A$12,0) -> 1
A13: 8 Ene | C13: 8.97 | D13: 5.52 | E13: 10 | F13: 9 | G13: 6.5 | H13: 5 | I13: 5 | J13: 3.75 | K13: 5.25 | L13: 1.75 | M13: 1.75 | N13: 4.75 | O13: 5.25 | P13: 2.75 | Q13: 0.75 | R13: 1.25 | S13: 9 | T13: 6 | U13: 4 | W13: =LEFT(A13,FIND(" ",A13)) -> 8 | X13: =MATCH(MID(A13,LEN(W13)+1,3),Sheet4!$A$1:$A$12,0) -> 1
A14: 9 Ene | C14: 8.97 | D14: 5.52 | E14: 10 | F14: 9 | G14: 6.5 | H14: 5 | I14: 5 | J14: 3.75 | K14: 5.25 | L14: 1.75 | M14: 1.75 | N14: 4.75 | O14: 5.25 | P14: 2.75 | Q14: 0.75 | R14: 1.25 | S14: 9 | T14: 6 | U14: 4 | W14: =LEFT(A14,FIND(" ",A14)) -> 9 | X14: =MATCH(MID(A14,LEN(W14)+1,3),Sheet4!$A$1:$A$12,0) -> 1
A15: 10 Ene | C15: 8.97 | D15: 5.52 | E15: 10 | F15: 9 | G15: 6.5 | H15: 5 | I15: 5 | J15: 3.75 | K15: 5.25 | L15: 1.75 | M15: 1.75 | N15: 4.75 | O15: 5.25 | P15: 2.75 | Q15: 0.75 | R15: 1.25 | S15: 9 | T15: 6 | U15: 4 | W15: =LEFT(A15,FIND(" ",A15)) -> 10 | X15: =MATCH(MID(A15,LEN(W15)+1,3),Sheet4!$A$1:$A$12,0) -> 1
A16: 11 Ene | C16: 8.97 | D16: 5.52 | E16: 10 | F16: 9 | G16: 6.5 | H16: 5 | I16: 5 | J16: 3.75 | K16: 5.25 | L16: 1.75 | M16: 1.75 | N16: 4.75 | O16: 5.25 | P16: 2.75 | Q16: 0.75 | R16: 1.25 | S16: 9 | T16: 6 | U16: 4 | W16: =LEFT(A16,FIND(" ",A16)) -> 11 | X16: =MATCH(MID(A16,LEN(W16)+1,3),Sheet4!$A$1:$A$12,0) -> 1
A17: 12 Ene | C17: 8.97 | E17: 10 | F17: 9 | G17: 6.5 | H17: 5 | I17: 5 | J17: 3.75 | K17: 5.25 | L17: 1.75 | M17: 1.75 | N17: 4.75 | O17: 5.25 | P17: 2.75 | Q17: 0.75 | R17: 1.25 | S17: 9 | T17: 6 | U17: 4 | W17: =LEFT(A17,FIND(" ",A17)) -> 12 | X17: =MATCH(MID(A17,LEN(W17)+1,3),Sheet4!$A$1:$A$12,0) -> 1
A18: 13 Ene | E18: 10 | F18: 9 | G18: 6.5 | H18: 5 | I18: 5 | J18: 3.75 | K18: 5.25 | L18: 1.75 | M18: 1.75 | N18: 4.75 | O18: 5.25 | P18: 2.75 | Q18: 0.75 | R18: 1.25 | S18: 9 | T18: 6 | U18: 4 | W18: =LEFT(A18,FIND(" ",A18)) -> 13 | X18: =MATCH(MID(A18,LEN(W18)+1,3),Sheet4!$A$1:$A$12,0) -> 1
A19: 14 Ene | D19: 5.52 | E19: 10 | F19: 9 | G19: 6.5 | H19: 5 | I19: 5 | J19: 3.75 | K19: 5.25 | L19: 1.75 | M19: 1.75 | N19: 4.75 | O19: 5.25 | P19: 2.75 | Q19: 0.75 | R19: 1.25 | S19: 9 | T19: 6 | U19: 4 | W19: =LEFT(A19,FIND(" ",A19)) -> 14 | X19: =MATCH(MID(A19,LEN(W19)+1,3),Sheet4!$A$1:$A$12,0) -> 1
A20: 15 Ene | C20: 8.97 | D20: 5.52 | E20: 10 | F20: 9 | G20: 6.5 | H20: 5 | I20: 5 | J20: 3.75 | K20: 5.25 | L20: 1.75 | M20: 1.75 | N20: 4.75 | O20: 5.25 | P20: 2.75 | Q20: 0.75 | R20: 1.25 | S20: 9 | T20: 6 | U20: 4 | W20: =LEFT(A20,FIND(" ",A20)) -> 15 | X20: =MATCH(MID(A20,LEN(W20)+1,3),Sheet4!$A$1:$A$12,0) -> 1
A21: 16 Ene | C21: 8.97 | D21: 5.52 | E21: 10 | F21: 9 | G21: 6.5 | H21: 5 | I21: 5 | J21: 3.75 | K21: 5.25 | L21: 1.75 | M21: 1.75 | N21: 4.75 | O21: 5.25 | P21: 2.75 | Q21: 0.75 | R21: 1.25 | S21: 9 | T21: 6 | U21: 4 | W21: =LEFT(A21,FIND(" ",A21)) -> 16 | X21: =MATCH(MID(A21,LEN(W21)+1,3),Sheet4!$A$1:$A$12,0) -> 1
A22: 17 Ene | C22: 8.97 | D22: 5.52 | E22: 10 | F22: 9 | G22: 6.5 | H22: 5 | I22: 5 | J22: 3.75 | K22: 5.25 | L22: 1.75 | M22: 1.75 | N22: 4.75 | O22: 5.25 | P22: 2.75 | Q22: 0.75 | R22: 1.25 | S22: 9 | T22: 6 | U22: 4 | W22: =LEFT(A22,FIND(" ",A22)) -> 17 | X22: =MATCH(MID(A22,LEN(W22)+1,3),Sheet4!$A$1:$A$12,0) -> 1
A23: 18 Ene | C23: 8.97 | D23: 5.52 | E23: 10 | F23: 9 | G23: 6.5 | H23: 5 | I23: 5 | J23: 3.75 | K23: 5.25 | L23: 1.75 | M23: 1.75 | N23: 4.75 | O23: 5.25 | P23: 2.75 | Q23: 0.75 | R23: 1.25 | S23: 9 | T23: 6 | U23: 4 | W23: =LEFT(A23,FIND(" ",A23)) -> 18 | X23: =MATCH(MID(A23,LEN(W23)+1,3),Sheet4!$A$1:$A$12,0) -> 1
A24: 19 Ene | C24: 8.97 | E24: 10 | F24: 9 | G24: 6.5 | H24: 5 | I24: 5 | J24: 3.75 | K24: 5.25 | L24: 1.75 | M24: 1.75 | N24: 4.75 | O24: 5.25 | P24: 2.75 | Q24: 0.75 | R24: 1.25 | S24: 9 | T24: 5.75 | U24: 4 | W24: =LEFT(A24,FIND(" ",A24)) -> 19 | X24: =MATCH(MID(A24,LEN(W24)+1,3),Sheet4!$A$1:$A$12,0) -> 1
A25: 20 Ene | E25: 10 | F25: 9 | G25: 6.5 | H25: 5 | I25: 5 | J25: 3.75 | K25: 5.25 | L25: 1.75 | M25: 1.75 | N25: 4.75 | O25: 5.25 | P25: 2.75 | Q25: 0.75 | R25: 1.25 | S25: 9 | T25: 5.75 | U25: 4 | W25: =LEFT(A25,FIND(" ",A25)) -> 20 | X25: =MATCH(MID(A25,LEN(W25)+1,3),Sheet4!$A$1:$A$12,0) -> 1
A26: 21 Ene | D26: 5.52 | E26: 10 | F26: 9 | G26: 6.5 | H26: 5 | I26: 5 | J26: 3.75 | K26: 5.25 | L26: 1.75 | M26: 1.75 | N26: 4.75 | O26: 5.25 | P26: 2.75 | Q26: 0.75 | R26: 1.25 | S26: 9 | T26: 5.75 | U26: 4 | W26: =LEFT(A26,FIND(" ",A26)) -> 21 | X26: =MATCH(MID(A26,LEN(W26)+1,3),Sheet4!$A$1:$A$12,0) -> 1
A27: 22 Ene | C27: 8.97 | D27: 5.52 | E27: 10 | F27: 9 | G27: 6.5 | H27: 5 | I27: 5 | J27: 3.75 | K27: 5.25 | L27: 1.75 | M27: 1.75 | N27: 4.75 | O27: 5.25 | P27: 2.75 | Q27: 0.75 | R27: 1.25 | S27: 9 | T27: 5.75 | U27: 4 | W27: =LEFT(A27,FIND(" ",A27)) -> 22 | X27: =MATCH(MID(A27,LEN(W27)+1,3),Sheet4!$A$1:$A$12,0) -> 1
A28: 23 Ene | C28: 8.97 | D28: 5.52 | E28: 10 | F28: 9 | G28: 6.5 | H28: 5 | I28: 5 | J28: 3.75 | K28: 5.25 | L28: 1.75 | M28: 1.75 | N28: 4.75 | O28: 5.25 | P28: 2.75 | Q28: 0.75 | R28: 1.25 | S28: 9 | T28: 5.75 | U28: 4 | W28: =LEFT(A28,FIND(" ",A28)) -> 23 | X28: =MATCH(MID(A28,LEN(W28)+1,3),Sheet4!$A$1:$A$12,0) -> 1
A29: 24 Ene | C29: 8.97 | D29: 5.52 | E29: 10 | F29: 9 | G29: 6.5 | H29: 5 | I29: 5 | J29: 3.75 | K29: 5.25 | L29: 1.75 | M29: 1.75 | N29: 4.75 | O29: 5.25 | P29: 2.75 | Q29: 0.75 | R29: 1.25 | S29: 9 | T29: 5.75 | U29: 4 | W29: =LEFT(A29,FIND(" ",A29)) -> 24 | X29: =MATCH(MID(A29,LEN(W29)+1,3),Sheet4!$A$1:$A$12,0) -> 1
A30: 25 Ene | C30: 8.97 | D30: 5.52 | E30: 10 | F30: 9 | G30: 6.5 | H30: 5 | I30: 5 | J30: 3.75 | K30: 5.25 | L30: 1.75 | M30: 1.75 | N30: 4.75 | O30: 5.25 | P30: 2.75 | Q30: 0.75 | R30: 1.25 | S30: 9 | T30: 5.75 | U30: 4 | W30: =LEFT(A30,FIND(" ",A30)) -> 25 | X30: =MATCH(MID(A30,LEN(W30)+1,3),Sheet4!$A$1:$A$12,0) -> 1
A31: 26 Ene | C31: 8.97 | E31: 10 | F31: 9 | G31: 6.5 | H31: 5 | I31: 5 | J31: 3.75 | K31: 5.25 | L31: 1.75 | M31: 1.75 | N31: 4.75 | O31: 5.25 | P31: 2.75 | Q31: 0.75 | R31: 1.25 | S31: 9 | T31: 5.75 | U31: 4 | W31: =LEFT(A31,FIND(" ",A31)) -> 26 | X31: =MATCH(MID(A31,LEN(W31)+1,3),Sheet4!$A$1:$A$12,0) -> 1
A32: 27 Ene | E32: 10 | F32: 9 | G32: 6.5 | H32: 5 | I32: 5 | J32: 3.75 | K32: 5.25 | L32: 1.75 | M32: 1.75 | N32: 4.75 | O32: 5.25 | P32: 2.75 | Q32: 0.75 | R32: 1.75 | S32: 9 | T32: 5.75 | U32: 4 | W32: =LEFT(A32,FIND(" ",A32)) -> 27 | X32: =MATCH(MID(A32,LEN(W32)+1,3),Sheet4!$A$1:$A$12,0) -> 1
A33: 28 Ene | D33: 5.52 | E33: 10 | F33: 9 | G33: 6.5 | H33: 5 | I33: 5 | J33: 3.75 | K33: 5.25 | L33: 1.75 | M33: 1.75 | N33: 4.75 | O33: 5.25 | P33: 2.75 | Q33: 0.75 | R33: 1.75 | S33: 9 | T33: 5.75 | U33: 4 | W33: =LEFT(A33,FIND(" ",A33)) -> 28 | X33: =MATCH(MID(A33,LEN(W33)+1,3),Sheet4!$A$1:$A$12,0) -> 1
A34: 29 Ene | C34: 8.97 | D34: 5.52 | E34: 10 | F34: 9 | G34: 6.5 | H34: 5 | I34: 5 | J34: 3.75 | K34: 5.25 | L34: 1.75 | M34: 1.75 | N34: 4.75 | O34: 5.25 | P34: 2.75 | Q34: 0.75 | R34: 1.75 | S34: 9 | T34: 5.75 | U34: 4 | W34: =LEFT(A34,FIND(" ",A34)) -> 29 | X34: =MATCH(MID(A34,LEN(W34)+1,3),Sheet4!$A$1:$A$12,0) -> 1
A35: 30 Ene | C35: 5.98 | D35: 5.52 | E35: 10 | F35: 9 | G35: 6.5 | H35: 5 | I35: 5 | J35: 3.75 | K35: 5.25 | L35: 1.75 | M35: 1.75 | N35: 4.75 | O35: 5.25 | P35: 2.25 | Q35: 0.75 | R35: 1.75 | S35: 9 | T35: 5.75 | W35: =LEFT(A35,FIND(" ",A35)) -> 30 | X35: =MATCH(MID(A35,LEN(W35)+1,3),Sheet4!$A$1:$A$12,0) -> 1
A36: 31 Ene | C36: 5.98 | D36: 5.99 | E36: 10 | F36: 9 | G36: 6.5 | H36: 5 | I36: 5 | J36: 3.75 | K36: 5.25 | L36: 1.75 | M36: 1.75 | N36: 4.75 | O36: 5.25 | P36: 2.25 | Q36: 0.75 | R36: 1.75 | S36: 9 | T36: 5.75 | W36: =LEFT(A36,FIND(" ",A36)) -> 31 | X36: =MATCH(MID(A36,LEN(W36)+1,3),Sheet4!$A$1:$A$12,0) -> 1
A37: 1 Feb | C37: 5.98 | D37: 5.99 | E37: 10 | F37: 9 | G37: 6.5 | H37: 5 | I37: 5 | J37: 3.75 | K37: 5.25 | L37: 1.75 | M37: 1.75 | N37: 5 | O37: 5.25 | P37: 2.25 | Q37: 0.75 | R37: 1.75 | S37: 9 | T37: 5.75 | W37: =LEFT(A37,FIND(" ",A37)) -> 1 | X37: =MATCH(MID(A37,LEN(W37)+1,3),Sheet4!$A$1:$A$12,0) -> 2
A38: 2 Feb | C38: 5.98 | E38: 10 | F38: 9 | G38: 6.5 | H38: 5 | I38: 5 | J38: 3.75 | K38: 4.75 | L38: 1.75 | M38: 1.75 | N38: 5 | O38: 5.25 | P38: 2.25 | Q38: 0.75 | R38: 1.75 | S38: 9 | T38: 5.75 | W38: =LEFT(A38,FIND(" ",A38)) -> 2 | X38: =MATCH(MID(A38,LEN(W38)+1,3),Sheet4!$A$1:$A$12,0) -> 2
A39: 3 Feb | E39: 10 | F39: 9 | G39: 6.5 | H39: 5 | I39: 5 | J39: 3.75 | K39: 4.75 | L39: 1.75 | M39: 1.75 | N39: 5 | O39: 5.25 | P39: 2.25 | Q39: 0.75 | R39: 1.75 | S39: 9 | T39: 5.75 | W39: =LEFT(A39,FIND(" ",A39)) -> 3 | X39: =MATCH(MID(A39,LEN(W39)+1,3),Sheet4!$A$1:$A$12,0) -> 2
A40: 4 Feb | D40: 5.99 | E40: 10 | F40: 9 | G40: 6.5 | H40: 5 | I40: 5 | J40: 3.75 | K40: 4.75 | L40: 1.75 | M40: 1.75 | N40: 5 | O40: 5.25 | P40: 2.25 | Q40: 0.75 | R40: 1.75 | S40: 9 | T40: 5.75 | W40: =LEFT(A40,FIND(" ",A40)) -> 4 | X40: =MATCH(MID(A40,LEN(W40)+1,3),Sheet4!$A$1:$A$12,0) -> 2
A41: 5 Feb | C41: 5.98 | D41: 5.99 | E41: 10 | F41: 9 | G41: 6.5 | H41: 5 | I41: 5 | J41: 3.75 | K41: 4.75 | L41: 1.75 | M41: 1.75 | N41: 5 | O41: 5.25 | P41: 2.25 | Q41: 0.75 | R41: 1.75 | S41: 9 | T41: 5.75 | W41: =LEFT(A41,FIND(" ",A41)) -> 5 | X41: =MATCH(MID(A41,LEN(W41)+1,3),Sheet4!$A$1:$A$12,0) -> 2
A42: 6 Feb | C42: 5.98 | D42: 5.99 | E42: 10 | F42: 9 | G42: 6.5 | H42: 5 | I42: 5 | J42: 3.75 | K42: 4.75 | L42: 1.75 | M42: 1.75 | N42: 5 | O42: 5.25 | P42: 2.25 | Q42: 0.75 | R42: 1.75 | S42: 9 | T42: 5.75 | W42: =LEFT(A42,FIND(" ",A42)) -> 6 | X42: =MATCH(MID(A42,LEN(W42)+1,3),Sheet4!$A$1:$A$12,0) -> 2
...

Sheet TC
A1: Tipo cambio de compra y de venta del dólar de los Estados Unidos de América
A2: Referencia del Banco Central de Costa Rica
A3: En colones costarricenses
B5: TIPO CAMBIO COMPRA | C5: TIPO DE CAMBIO VENTA
A6: 1 Ene 1983 | B6: 44.95 | C6: 45.45 | E6: 30317
A7: 2 Ene 1983 | B7: 44.95 | C7: 45.45 | E7: =+E6+1 -> 30318
A8: 3 Ene 1983 | B8: 44.95 | C8: 45.45 | E8: =+E7+1 -> 30319
A9: 4 Ene 1983 | B9: 44.95 | C9: 45.45 | E9: =+E8+1 -> 30320
A10: 5 Ene 1983 | B10: 44.95 | C10: 45.45 | E10: =+E9+1 -> 30321
A11: 6 Ene 1983 | B11: 44.95 | C11: 45.45 | E11: =+E10+1 -> 30322
A12: 7 Ene 1983 | B12: 44.95 | C12: 45.45 | E12: =+E11+1 -> 30323
A13: 8 Ene 1983 | B13: 44.95 | C13: 45.45 | E13: =+E12+1 -> 30324
A14: 9 Ene 1983 | B14: 44.95 | C14: 45.45 | E14: =+E13+1 -> 30325
A15: 10 Ene 1983 | B15: 44.95 | C15: 45.45 | E15: =+E14+1 -> 30326
A16: 11 Ene 1983 | B16: 44.9 | C16: 45.4 | E16: =+E15+1 -> 30327
A17: 12 Ene 1983 | B17: 44.9 | C17: 45.4 | E17: =+E16+1 -> 30328
A18: 13 Ene 1983 | B18: 44.9 | C18: 45.4 | E18: =+E17+1 -> 30329
... A15396: 19 Feb 2025 | B15396: 503.24 | C15396: 508.54 | E15396: =+E15395+1 -> 45707

Sheet Sheet4
A1: Ene
A2: Feb
A3: Mar
A4: Abr
A5: May
A6: Jun
A7: Jul
A8: Ago
A9: Set
A10: Oct
A11: Nov
A12: Dic
